Workbook

Sheet 0.읽어주세요
A1: 자료 요청 서식
A4: 한 줄 요약 | B4: 비용은 '총액'으로, 인원은 '몇 명'으로 적어 주시면 됩니다. 1인당 금액은 저희가 나눠서 계산합니다.
A6: 작성 원칙 세 가지
A7: 1 | B7: 1인당 금액을 계산해 주지 않으셔도 됩니다. 예를 들어 '1일 급식단가'가 아니라 '급식비 집행액'과 '1일 평균 수용인원'을 각각 적어 주십시오.
A8: 2 | B8: 이미 있는 자료를 그대로 보내주셔도 됩니다. 결산서, 사업설명자료, 운영실적 보고, 교정통계연보 발췌 등 보유 형태 그대로도 좋습니다.
A9: 3 | B9: 없는 항목은 비워 두시고 사유만 적어 주십시오. 각 시트 맨 아래에 사유 칸을 두었습니다. 전부 채우지 못하셔도 됩니다.
A11: 시트 보는 법
A12: 흰 칸 | B12: 적어 주실 칸입니다.
A13: 회색 칸 (맨 오른쪽 '비고') | B13: 저희 연구 모델에서 그 자료가 어느 변수로 쓰이는지 표시한 것입니다. 담당자님께서 손대실 필요 없습니다.
A14: 노란 칸 | B14: 이해를 돕기 위한 예시입니다. 지우고 쓰셔도 되고 그대로 두셔도 됩니다.
A15: 빨간 글씨 | B15: 특히 유의해 주실 점입니다.
A17: 가장 먼저 부탁드리는 세 가지 | B17: 서식 9 (이수 여부별 재복역 교차표) · 서식 4 (재활교육 운영실적) · 서식 6 (재활 예산 집행내역)
B18: 이 셋이 없으면 분석 자체가 성립하지 않습니다. 나머지가 늦어져도 이 셋은 부탁드립니다.

Sheet 1.요청표
A1: 요청표 — 한눈에 보기
A2: 총 13건. 2026-10-21 기준: 완료 1, 부분 6, 미회신 5, 문헌 대체 1. 상세는 「취합현황」 시트(자동 생성), 계산은 「원단위계산」 시트.
A4: 번호 | B4: 요청 자료 | C4: 왜 필요한가 (한 줄) | D4: 작성할 시트 | E4: 예상 소관 | F4: 중요도 | G4: 진행 상태 | H4: 이 자료로 채우는 모델 KEY
A5: 1 | B5: 교정 분야 세출예산 집행내역 | C5: 수용자 1인당 원가를 계산할 때 나눗셈의 '위쪽'(총액)이 됩니다. | D5: 서식 1 | E5: 교정본부 복지과 | F5: 높음 | G5: 부분 (8/10) | H5: IN-C-02~11, PG-C-01
A6: 2 | B6: 수용인원 현황 | C6: 위 총액을 나눌 '아래쪽'(인원)입니다. 이게 없으면 1인당 금액이 안 나옵니다. | D6: 서식 2 | E6: 교정본부 보안과 | F6: 높음 | G6: 부분 (5/6) | H6: IN-N-01·02·03·07·08
A7: 3 | B7: 마약류사범 수용현황 | C7: 전체 수용자가 아니라 마약류사범 기준으로 계산하기 위해 필요합니다. | D7: 서식 3 | E7: 교정본부 보안과 | F7: 높음 | G7: 미회신 (0/9) | H7: IN-N-04·05·06·08
A8: 4 | B8: 마약사범 재활교육 운영실적 | C8: 재활 프로그램 1인당 비용의 '아래쪽'(인원)이자 효과 분석의 대상 규모입니다. | D8: 서식 4 | E8: 마약사범재활팀 | F8: 가장 높음 | G8: 부분 (이수만) | H8: PG-N-01·02·03, PG-D-01
A9: 5 | B9: 재활 전담인력 현황 | C9: 인건비 중 얼마를 재활 프로그램 비용으로 볼지 정하는 데 씁니다. | D9: 서식 5 | E9: 마약사범재활팀 | F9: 보통 | G9: 완료 (4/4 기관) | H9: PG-C-04, PG-D-02
A10: 6 | B10: 마약사범 재활 예산 집행내역 | C10: 재활 프로그램 1인당 비용의 '위쪽'(총액)입니다. | D10: 서식 6 | E10: 교정본부 복지과 | F10: 가장 높음 | G10: 부분 (총액만) | H10: PG-C-02·03·05·06·07
A11: 7 | B11: 의료·약물검사 실적 및 비용 | C11: 중독자에 대한 치료개입 1인당 비용을 계산합니다. | D11: 서식 7 | E11: 교정본부 의료과 | F11: 보통 | G11: 부분 (4/13) | H11: TX-C-01~07, TX-N-01~04
A12: 8 | B12: 출소 및 재복역 현황 | C12: 재범이 원래 얼마나 일어나는지(기준선)를 확인합니다. | D12: 서식 8 | E12: 마약사범재활팀 | F12: 높음 | G12: 미회신 (0/6) | H12: OC-01·02·05
A13: 9 | B13: 재활교육 이수 여부별 재복역 교차표 | C13: 재활교육이 재범을 얼마나 줄이는지 계산합니다. 13건 중 가장 중요합니다. | D13: 서식 9 | E13: 마약사범재활팀 | F13: 가장 높음 | G13: 문헌 대체 (문헌) | H13: OC-03 → Δr, r0
A14: 10 | B14: 이수·미이수 집단의 인적 특성 | C14: 두 집단이 원래 비슷한 사람들이었는지 확인합니다. | D14: 서식 10 | E14: 마약사범재활팀 | F14: 보통 | G14: 미회신 (0/6) | H14: OC-04
A15: 11 | B15: 통계 산출기준 정의서 | C15: 같은 '인원'이라도 정의가 다르면 1인당 금액이 달라집니다. 짧은 설명이면 충분합니다. | D15: 서식 11 | E15: 각 소관과 | F15: 높음 | G15: 미회신 (0/6) | H15: MT-04
... A17: 별도 | B17: 치료보호·보호관찰 예산 및 인원 | C17: 출소 후 사후관리 비용입니다. 교정본부 소관이 아니라 별도 요청이 필요합니다. | D17: 별도요청 | E17: 복지부·범죄예방정책국·치료처우과 | F17: 가장 높음 | G17: 부분 (4/9) | H17: CU-C-01·03, CU-N-01·02
A19: ※ '이 자료로 채우는 모델 KEY'는 연구진이 쓰는 내부 식별자입니다. 담당자께서 신경 쓰지 않으셔도 되며, 각 서식의 맨 오른쪽 비고란에도 같은 값을 적어 두었습니다.

Sheet 취합현황
A1: 자료 요청 13건 취합 현황 (2026-10-21, v3)
A2: 이 시트는 data/dashboard.json에서 자동으로 만들어집니다. 여기서 고치지 말고 dashboard.json을 고치십시오. 상태: 완료 1 · 부분 6 · 미회신 5 · 문헌 대체 1
A4: 번호 | B4: 요청 자료 | C4: 상태 | D4: 회신 항목 | E4: 회신일 | F4: 받은 내용 | G4: 빠진 내용 | H4: 모델 반영 | I4: 비고 | J4: 진행 중 | K4: 소관
A5: 1 | B5: 교정 세출예산 집행내역 | C5: 부분 | D5: 8/10 | E5: 2026-09-07 | F5: 2025 집행액 8항목, 교도소 일반회계 총결산 1조 6,992억 원 | G5: 8번 교정시설 취득, 10번 교도작업특별회계 | H5: UC-01·UC-02 | I5: 취득비가 빠져 UC-01은 하한 | J5: 두 항목 재요청, 총결산과 8항목 합의 차이(약 1,734억) 구성 문의 | K5: 교정본부 복지과
A6: 2 | B6: 수용인원 현황 | C6: 부분 | D6: 5/6 | E6: 2026-09-07 | F6: 1일 평균 63,680 · 정원 50,614 · 수용률 125.8% · 신입·출소 · 기관별 54개 | G6: 수용 연인원(연말 현원 64,626명이 대신 기재) | H6: UC-01 분모 | I6: 연인원은 1일 평균×365로 대체 가능 | J6: 연인원 정의 확인 | K6: 교정본부 보안과
A7: 3 | B7: 마약류사범 수용현황 | C7: 미회신 | D7: 0/9 | E7: 2026-09-07 | F7: 연말 현원 7,429명뿐(요청 항목 아님) | G7: 1일 평균, 향정 구분, 연인원, 형기 분포, 신입·출소 | H7: 미반영 | I7: 사유: 공식 통계로 미집계 | J7: 교정통계연보 죄명별 표로 대체 검토 | K7: 교정본부 보안과
A8: 4 | B8: 재활교육 운영실적 ◆ | C8: 부분 | D8: 1/4 | E8: 2026-09-07 | F8: 2024~2026.7 과정별 이수 인원(전국 합계) | G8: 기수, 개시, 중도탈락 인원·사유, 기관별 구분 | H8: UC-07·UC-06 분모 | I8: 개시·탈락이 없어 1인당 원가는 과대 쪽 | J8: 중도탈락 인원 재요청 | K8: 마약사범재활팀
A9: 5 | B9: 재활 전담인력 현황 | C9: 완료 | D9: 4/4 | E9: 2026-09-07 | F9: 4개 과 각 11명, 직급 구성, 투입비율 64.0·68.2% | G9: - | H9: PG-C-04·PG-D-02 | I9: 2026 신설 조직을 2025 원가의 대리값으로 사용 | K9: 마약사범재활팀
A10: 6 | B10: 재활 예산 집행내역 ◆ | C10: 부분 | D10: 0/8 | E10: 2026-09-07 | F10: 재활 관련 예산 총액 5,999,392,000원 | G10: 비목별 8항목 전부(산출 불가) | H10: PG 비용풀 | I10: 비목 구분은 교정교화 사업 내에서만 가능 | J10: 예산/집행 구분, 중독재활수용동 설치비 포함 여부 확인 | K10: 교정본부 복지과
A11: 7 | B11: 의료·약물검사 실적 | C11: 부분 | D11: 4/13 | E11: 2026-09-07 | F11: 2021~25 의료비 총액·건보 예탁금, 진료 건수, 외부진료 인원 | G11: 세부 의료비, 의료 인건비, 정신과 약제비, 약물검사, 치료개입 대상 인원(미생산) | H11: 참고값만 | I11: 금액이 "원"으로 표기됐으나 천원으로 추정 | J11: 의료과에 단위 확인(최우선) | K11: 교정본부 의료과
A12: 8 | B12: 출소 및 재복역 현황 | C12: 미회신 | D12: 0/6 | E12: 미회신 | F12: - | G12: 출소연도별 3년 내 재복역, 경과기간별 재복역 | H12: hₜ 가정값 사용 | I12: 2024·25 출소자는 3년 추적이 불가능한 요청이었음 | J12: 2019~2022 출소 코호트로 범위 수정해 재요청 | K12: 마약사범재활팀
A13: 9 | B13: 이수별 재복역 교차표 ◆ | C13: 문헌 대체 | D13: 0/4 | E13: 미회신 | F13: 김도균·나종민(2025) 931명 표본(이수 439/재복역 178, 미이수 492/재복역 247) | G13: 현행 4단계 과정 기준, 과정유형별 결과 | H13: r0·Δr | I13: 구 과정(16~134시간) 대상 | J13: 현행 과정 기준 교차표 요청(논문 제1저자가 마약사범재활팀) | K13: 마약사범재활팀
A14: 10 | B14: 이수·미이수 인적특성 | C14: 미회신 | D14: 0/6 | E14: 미회신 | F14: 논문 전체 표본 기술통계만 | G14: 집단별 연령·형기·전과·징벌 | H14: 미반영 | I14: 집단 간 균형(SMD) 진단 불가 | J14: 서식 9와 함께 요청 | K14: 마약사범재활팀
A15: 11 | B15: 통계 산출기준 정의서 | C15: 미회신 | D15: 0/6 | E15: 미회신 | F15: - | G15: 1일 평균·연인원·이수 인원·재복역률 정의 | H15: 미반영 | J15: 전화 확인으로 대체 | K15: 각 소관과
A16: 12 | B16: 교정통계연보 표목록 | C16: 미회신 | D16: 0/1 | E16: 미회신 | F16: - | G16: 표목록(서식 시트 자체가 파일에 없음) | H16: 미반영 | J16: 교정통계연보 2025 직접 확보 | K16: 교정기획과
A17: 별도 | B17: 치료보호·보호관찰 | C17: 부분 | D17: 4/9 | E17: 2026-09-29 | F17: 보호관찰 대상 3,675→5,391명, 치료명령 234→332명, 국립법무병원 결산 85.1→123.6억, 2호 24~31명 | G17: 복지부 치료보호 예산·집행·인원·기관(4항목), 보호관찰 예산(산출 불가) | H17: UC-12 미산출 | I17: 치료보호 인원은 범죄백서 표 3-82로 대체 가능 | J17: 복지부 공문 재발송 | K17: 복지부·범죄예방정책국·치료처우과
A18: 추가 | B18: 대검찰청 정보공개 | C18: 추가 반영 | D18: - | E18: 2026-10-07 | F18: 검찰 결산 2024 1조 2,163억, 형사 검거인원 1,405,185명, 마약류 검거인원 | G18: 2025 전체 형사사건 | H18: SCᵣ 검찰 단계 | J18: 같은 파일의 교정영역 질문지 회신 대기 여부 확인 | K18: 대검찰청

Sheet 원단위계산
A1: 원단위·증분비용·손익분기 계산 (2025년 기준, 2026-10-21 취합본)
A2: 글자색: 파랑=직접 입력값(회신·문헌), 초록=다른 시트 연결, 검정=계산식. 노란 칸=연구진 가정(바꾸면 전체 재계산). 주황 칸=핵심 결과. UC-10(치료개입)·UC-12(사후관리)는 자료 미비로 0 처리 → ΔC는 하한값.
A4: A. 투옥 원가중심점 (IN-C / IN-N) → UC-01 총원가, UC-02 변동원가
A5: IN-N-01 | B5: 1일 평균 수용인원(전국, 2025) | C5: ='서식2 수용인원'!D7 | D5: 명 | E5: 서식2 1번(보안과)
B6: 연 일수 | C6: 365 | D6: 일 | E6: 가정
A7: IN-C-02 | B7: 급식비 | C7: ='서식1 세출예산'!D7 | D7: 원 | E7: 서식1 1번(복지과)
A8: IN-C-03 | B8: 피복·침구비 | C8: ='서식1 세출예산'!D8 | D8: 원 | E8: 서식1 2번
A9: IN-C-04 | B9: 공공요금 | C9: ='서식1 세출예산'!D9 | D9: 원 | E9: 서식1 3번
A10: IN-C-05 | B10: 일반수용비·기타 물건비 | C10: ='서식1 세출예산'!D10 | D10: 원 | E10: 서식1 4번
A11: IN-C-06 | B11: 교도소운영 인건비 | C11: ='서식1 세출예산'!D11 | D11: 원 | E11: 서식1 5번
A12: PG-C-01 | B12: 교정·교화 사업 | C12: ='서식1 세출예산'!D12 | D12: 원 | E12: 서식1 6번. 재활예산(서식6)을 포함하므로 UC-01에 넣으면 재활비가 이중으로 잡힘 → 아래 UC-01a에서는 제외
A13: IN-C-08 | B13: 교정시설장비 운용·현대화 | C13: ='서식1 세출예산'!D13 | D13: 원 | E13: 서식1 7번
A14: IN-C-10 | B14: 교정본부·지방교정청 공통관리비 | C14: ='서식1 세출예산'!D15 | D14: 원 | E14: 서식1 9번
B15: 교도소 일반회계 세출 결산 총액(2025) | C15: 1699217000000 | D15: 원 | E15: 복지과 별도 회신(hwpx "자료요청 2차"). 의료비·직업훈련 등 서식1 미분류 항목 포함
B16: 회신 항목 합계(교정·교화 제외) | C16: =$C$7+$C$8+$C$9+$C$10+$C$11+$C$13+$C$14 | D16: 원 | E16: 교정시설 취득(8번)·교도작업특별회계(10번) 미회신으로 빠짐
A17: UC-01a | B17: 수용 1인·연 총원가 (회신 항목 기준) | C17: =$C$16/$C$5 | D17: 원/인·년 | E17: 하한. 보고서 초안 2,396만 원은 교정·교화 포함값
A18: UC-01a | B18: 수용 1인·1일 총원가 (회신 항목 기준) | C18: =$C$17/$C$6 | D18: 원/인·일
A19: UC-01b | B19: 수용 1인·연 총원가 (일반회계 결산 총액 기준) | C19: =($C$15-$C$12)/$C$5 | D19: 원/인·년 | E19: 상한. 결산 총액에서 교정·교화(재활 포함)만 제외
B20: 변동원가에 넣을 공공요금 비율 | C20: 0.5 | E20: 가정: 공공요금은 수용인원에 반쯤 비례(준변동비)
A21: UC-02 | B21: 수용 1인·1일 변동원가(한계원가) | C21: =($C$7+$C$8+$C$10+$C$9*$C$20)/$C$5/$C$6 | D21: 원/인·일 | E21: 급식+피복+일반수용비+공공요금×비율. 인건비·장비·관리비는 단기 고정비로 봄
A23: B. 투입 원가중심점 (PG-C / PG-N / PG-D) → UC-07 인시당 원가, UC-06 과정별 1인당 원가
A24: PG-C-02·03 | B24: 마약사범 재활 예산 총액(2025) | C24: ='서식6 재활예산'!D15 | D24: 원 | E24: 서식6(복지과). 비목 구분 불가, 예산/집행 구분과 시설비 포함 여부 확인 필요
A25: PG-C-04 | B25: 직급 | C25: 화성직훈(교) | D25: 부산(교) | E25: 청주여자(교) | F25: 광주(교) | G25: 월 봉급(원) | H25: 출처: 직급 구성=서식5 비고(마약사범재활팀, 2026 정원). 월 봉급=인사혁신처 2026 일반직 봉급표 10호봉(가정).
B26: 5급 | C26: 1 | D26: 1 | E26: 1 | F26: 1 | G26: 4066800
B27: 6급 | C27: 3 | D27: 2 | E27: 1 | F27: 2 | G27: 3468700
B28: 7급 | C28: 1 | D28: 4 | E28: 1 | F28: 3 | G28: 3133300
B29: 8급 | C29: 2 | D29: 4 | E29: 3 | F29: 2 | G29: 2813000
B30: 9급 | C30: 4 | D30: 0 | E30: 5 | F30: 3 | G30: 2542700
B31: 인원 합계 | C31: =SUM(C26:C30) | D31: =SUM(D26:D30) | E31: =SUM(E26:E30) | F31: =SUM(F26:F30)
B32: 프로그램 직접투입 비율 | C32: ='서식5 전담인력'!G8/100 | D32: ='서식5 전담인력'!G9/100 | E32: ='서식5 전담인력'!G10/100 | F32: ='서식5 전담인력'!G11/100
B33: 연 인건비(봉급×12×계수) | C33: =SUMPRODUCT(C26:C30,$G$26:$G$30)*12*$C$35 | D33: =SUMPRODUCT(D26:D30,$G$26:$G$30)*12*$C$35 | E33: =SUMPRODUCT(E26:E30,$G$26:$G$30)*12*$C$35 | F33: =SUMPRODUCT(F26:F30,$G$26:$G$30)*12*$C$35
B34: 직접투입 인건비 | C34: =C33*C32 | D34: =D33*D32 | E34: =E33*E32 | F34: =F33*F32
B35: 봉급 외 인건비 계수(수당·상여·복리·연금부담 포함) | C35: 1.6 | D35: 배 | E35: 가정: 연간 총인건비 ≈ 연 봉급×1.6. 보고서 초안의 24.3억 원은 계수 약 1.5에 해당
A36: PG-C-04 | B36: 전담인력 연 인건비 합계(44명) | C36: =SUM(C33:F33) | D36: 원 | E36: 2026년 4개 마약사범재활과 정원 기준
A37: PG-D-02 | B37: 그중 프로그램 직접투입분 | C37: =SUM(C34:F34) | D37: 원 | E37: 기관별 투입비율(64.0~68.2%) 적용
B38: 2025년 원가에 전담인력 인건비 반영(1=예, 0=아니오) | C38: 1 | E38: 가정: 4개 과는 2026.1 신설이므로 2025년에는 다른 인력이 수행. 2026 구조를 2025 대리값으로 씀
B39: PG 비용풀(재활예산 + 직접투입 인건비) | C39: =$C$24+$C$37*$C$38 | D39: 원
B41: 과정 | C41: 이수 인원(2025) | D41: 과정 시간 | E41: 이수 인시 | F41: UC-06 1인당 원가 | G41: ΔC 1인당 증분비용 | H41: 손익분기 SCᵣ* | I41: 부분 B/C
A42: PG-N-02 | B42: 기본 | C42: ='서식4 재활교육 실적'!G12 | D42: ='서식4 재활교육 실적'!D12 | E42: =C42*D42 | F42: =D42*$C$48 | G42: =F42+$C$55+$C$58+$C$59*$C$21 | H42: =G42/($C$70*$C$80) | I42: =$C$70*$C$94*$C$80/G42
A43: PG-N-02 | B43: 집중 | C43: ='서식4 재활교육 실적'!G13 | D43: ='서식4 재활교육 실적'!D13 | E43: =C43*D43 | F43: =D43*$C$48 | G43: =F43+$C$55+$C$58+$C$59*$C$21 | H43: =G43/($C$70*$C$80) | I43: =$C$70*$C$94*$C$80/G43
...

Sheet 장문자료 검토
A1: 내용이 긴 자료의 반영 범위 검토
A2: 보고서 초안과 백서는 전체를 반영하지 않고 아래 범위만 씁니다.
A4: 자료 | B4: 분량 | C4: 반영할 부분 | D4: 반영 위치 | E4: 주의·수정할 점 | F4: 이번 계산 반영
A5: 보고서 초안(10.18, hwpx) | B5: 약 9.6만 자, 6개 장 | C5: 4장 1~2절의 수용·재활 현황과 원가 서술은 회신값과 대부분 일치하므로 유지. 재활교육 4단계 이수 현황표, 전담인력 구성, 1인당 수용비(2,396만 원) 서술 | D5: 보고서 4장 1~2절 | E5: ① 2장 4절 2-2)의 CBA 방정식이 구 제안서 산식(B단약 등 4개 편익, PSM·DID)이라 인계 메모 산식으로 교체 필요 ② 4장 표2의 비목별 금액(19.8억·18.2억·22.0억)은 "추정"으로 적혀 있으나 근거가 없고 회신은 비목 산출 불가 → 삭제 ③ "투입 대비 6배 이상 절감, 압도적 경제성 입증" 문장은 계산 근거 없음 → 삭제 또는 본 시트 결과로 교체 ④ 4장 3절 1항 "단약 편익"은 인계 메모에서 삭제하기로 한 항목 ⑤ 김도균·나종민(2025)을 "성향점수 적용"으로 인용했으나 실제는 로지스틱·Cox 회귀(통제변수 투입). 로지스틱 결과는 비유의(p=.066) ⑥ 재범률 "2023 34.2%→2025 35.3%"는 백서 표 3-89(32.8%·34.5%·29.8%)와 다름 → 출처 확인 ⑦ 이수율 21.4%는 연간 이수 인원÷연말 현원으로 분모 성격이 다름(흐름÷재고). 마약류 출소 인원 회신 후 재산정 ⑧ 2026년 신설 인력 인건비를 2025년 원가에 합산한 점을 명시 | F5: 초안 수치는 대조용으로만 사용
A6: 2025 마약류 범죄백서 3장 국내 동향(PDF) | B6: 180쪽, 표 91개 | C6: 표 3-1(2025 단속 23,403명), 표 3-21·26(5년 단속·연령), 표 3-55(검찰 처분), 표 3-65·69(실형률·실형 기간 분포), 표 3-82~88(치료보호·치료감호·조건부 기소유예), 표 3-89·90(재범률) | D6: 보고서 1장·2장 현황, 3장 형사사법비용·SCᵣ, 5장 정책 제언(치료 연계 실적) | E6: 나머지(청별·월별·지역별·압수량·밀수 사례·국제공조)는 본 모형 변수와 무관하므로 인용만. 재범률은 "입건 전과 기준"이라 교정 재복역률(r0)과 정의가 다름 | F6: 표 3-69 향정 실형 기간 분포 → 평균 실형 2.45년(재수용 비용)
A7: 2025 마약류 범죄백서 4장 국제 동향(PDF) | B7: 86쪽 | C7: 1절 세계 동향 중 UNODC 2025 수치(약물사용장애 6,400만 명, 치료율 8.1%)만 | D7: 보고서 1장 배경(국제 규범·치료 접근성) | E7: 국제협약·공조수사 사례(2~4절)는 비용 모형과 무관 → 반영하지 않음 | F7: 반영 없음
A8: 김도균·나종민(2025), 형사정책연구 36(1) | B8: 35쪽 | C8: 표5 이수·미이수별 재복역(439/178, 492/247), 표6 Cox 위험비 0.805(p<.05), 표3 로지스틱 오즈비 0.768(p=.066), 2018 출소자 3년 내 재복역률 36.3%, 표본 기술통계 | D8: 모형 r0·r1·Δr 임시값, 효과 추정 방법 서술(4장 3절), 서식9·10 대체 근거 | E8: ①구 과정(기본 16·집중 26·심화 134시간) 대상이라 현행 40~160시간 과정에 그대로 쓰면 효과 과소 또는 과대 가능 ②향정·65세 이하·한국인 한정 ③추적 5~6.7년 누적이라 "3년 내" 정의와 다름 ④미이수 집단에 중도탈락 포함 여부 불명 | F8: r0=50.2%, Δr=19.2%, 3년 내 비중 79.6%(hₜ 가정)
A9: 대검찰청 정보공개 회신(hwpx) | B9: 1쪽 | C9: 검찰청 세출 결산, 2024 형사사건 검거인원, 마약류 검거 건수·인원 | D9: 3장 형사사법비용(검찰 단계), SCᵣ | E9: 2025 전체 형사사건은 빈칸. 교정영역 질문지는 미회신 상태 | F9: 검찰 1인당 비용 86.6만 원
A10: 자료요청 2차 회신(hwpx) | B10: 1쪽 | C10: 항목별 담당 부서, 교도소 일반회계 총결산 2024·2025 | D10: 요청표 소관 갱신, UC-01b | E10: - | F10: UC-01b 상한

Sheet 서식1 세출예산
A1: 서식 1. 교정 분야 세출예산 집행내역
A2: 무엇에 쓰나요 | B2: 수용자 1인당 원가를 계산할 때 나눗셈의 위쪽(총액)이 됩니다.
A3: 어디서 나오나요 | B3: 재정정보시스템(dBrain) 세부사업별 집행액 조회, 또는 법무부 결산서·사업설명자료.
A4: 꼭 봐주세요 | B4: 예산액이 아니라 집행액(결산액)을 적어 주십시오. 최근 의료비처럼 집행률이 100%를 크게 넘는 항목이 있어, 예산액으로는 실제 원가를 알 수 없습니다.
A6: 번호 | B6: 요청 항목 | C6: 단위 | D6: 2025년 | E6: 산출 가능 여부 | F6: 비고 (모델 KEY)
A7: 1 | B7: 급식비 집행액 | C7: 원 | D7: 121363000000 | E7: 회신(복지과, 26.9.7) | F7: IN-C-02 급식비
A8: 2 | B8: 피복·침구비(의류비) 집행액 | C8: 원 | D8: 7721000000 | E8: 회신(복지과, 26.9.7) | F8: IN-C-03 피복비
A9: 3 | B9: 공공요금(전기·수도·가스·연료) | C9: 원 | D9: 125514000000 | E9: 회신(복지과, 26.9.7) | F9: IN-C-04 공공요금
A10: 4 | B10: 일반수용비·기타 물건비 | C10: 원 | D10: 8395000000 | E10: 회신(복지과, 26.9.7) | F10: IN-C-05 일반운영비
A11: 5 | B11: 「교도소운영 인건비」 사업 집행액 | C11: 원 | D11: 1163188000000 | E11: 회신(복지과, 26.9.7) | F11: IN-C-06 인건비
A12: 6 | B12: 「교정·교화」 사업 집행액 | C12: 원 | D12: 11228000000 | E12: 회신(복지과, 26.9.7) | F12: PG-C-01 교화 총괄
A13: 7 | B13: 「교정시설장비 운용 및 현대화」 집행액 | C13: 원 | D13: 83719000000 | E13: 회신(복지과, 26.9.7) | F13: IN-C-08 시설장비
A14: 8 | B14: 「교정시설 취득」(신·증축) 집행액 | C14: 원 | E14: 미회신 | F14: IN-C-09 자본
A15: 9 | B15: 교정본부·지방교정청 운영비 및 인건비 | C15: 원 | D15: 4690000000 | E15: 회신(복지과, 26.9.7) | F15: IN-C-10 공통관리비
A16: 10 | B16: 교도작업특별회계 세출 결산액 | C16: 원 | E16: 미회신 | F16: IN-C-11 특별회계
B17: 예시) 2022년 급식비 = 89,594,299,410 원
A19: 산출이 어려운 항목의 이유 (한 줄이면 충분합니다)
A20: 회신 없음: 8번(교정시설 취득)·10번(교도작업특별회계). 별도 회신(hwpx): 교도소 일반회계 세출 결산 2024년 1,674,128,000,000원, 2025년 1,699,217,000,000원.
A23: ※ 세목 단위로 나누기 어려우시면 세부사업 총액만 적어 주셔도 됩니다. 일반회계와 교도작업특별회계는 꼭 구분해 주십시오.

Sheet 서식2 수용인원
A1: 서식 2. 수용인원 현황
A2: 무엇에 쓰나요 | B2: 서식 1의 총액을 나눌 인원입니다. 이 값이 있어야 1인당 금액이 나옵니다.
A3: 어디서 나오나요 | B3: 교정통계연보 제Ⅱ편(수용 현황), e-나라지표 「교정시설 1일 평균 수용인원」, 내부 행정통계.
A4: 꼭 봐주세요 | B4: '1일 평균 수용인원'과 '연말 재적인원'은 값이 다릅니다. 가능하면 1일 평균으로 부탁드립니다.
A6: 번호 | B6: 요청 항목 | C6: 단위 | D6: 2025년 | E6: 산출 가능 여부 | F6: 비고 (모델 KEY)
A7: 1 | B7: 1일 평균 수용인원 (전국) | C7: 명 | D7: 63680 | E7: 회신(보안과) | F7: IN-N-01 수용 분모
A8: 2 | B8: 수용 연인원 (인·일) | C8: 인·일 | E8: 미회신: 회신값 64,626명은 25.12.31 연말 현원(연인원 아님) | F8: IN-N-03 기간비례 분모
A9: 3 | B9: 수용정원 | C9: 명 | D9: 50614 | E9: 회신(보안과) | F9: IN-N-07 과밀도
A10: 4 | B10: 수용률 | C10: % | D10: 125.8 | E10: 회신(보안과) | F10: IN-N-07 과밀도
A11: 5 | B11: 연간 신입 인원 | C11: 명 | D11: 101115 | E11: 회신(보안과) | F11: IN-N-08 회전
A12: 6 | B12: 연간 출소 인원 | C12: 명 | D12: 68619 | E12: 회신(보안과) | F12: IN-N-08 회전
B13: 예시) 2022년 1일 평균 수용인원 = 51,117 명
A15: [추가] 기관별 1일 평균 수용인원 (있으시면 부탁드립니다)
A16: 기관 간 비교로 '수용인원이 한 명 줄면 실제로 얼마가 절감되는지'를 추정합니다. 없으시면 건너뛰셔도 됩니다.
A18: 번호 | B18: 요청 항목 | C18: 단위 | D18: 2025년 | E18: 산출 가능 여부 | F18: 비고 (모델 KEY)
A19: 1 | B19: 기관별 54개 기관 값은 「서식2-기관별(회신)」 시트로 옮김 | C19: 명 | F19: IN-N-02 기관별 분모
F20: IN-N-02 기관별 분모
F21: IN-N-02 기관별 분모
F22: IN-N-02 기관별 분모
F23: IN-N-02 기관별 분모
F24: IN-N-02 기관별 분모
F25: IN-N-02 기관별 분모
F26: IN-N-02 기관별 분모
F27: IN-N-02 기관별 분모
F28: IN-N-02 기관별 분모
F29: IN-N-02 기관별 분모
F30: IN-N-02 기관별 분모
F31: IN-N-02 기관별 분모
... F43: IN-N-02 기관별 분모
A47: 산출이 어려운 항목의 이유 (한 줄이면 충분합니다)

Sheet 서식2-기관별(회신)
A1: 서식 2 [추가] 기관별 1일 평균 수용인원 (2025년, 보안과 회신)
A3: 번호 | B3: 기관명 | C3: 1일 평균 수용인원(명) | D3: 비고 (모델 KEY)
A4: 1 | B4: 서울(구) | C4: 3265.0877 | D4: IN-N-02 기관별 분모
A5: 2 | B5: 안양(교) | C5: 2235.2 | D5: IN-N-02 기관별 분모
A6: 3 | B6: 수원(구) | C6: 2390.0986 | D6: IN-N-02 기관별 분모
A7: 4 | B7: 서울동부(구) | C7: 2797.4466 | D7: IN-N-02 기관별 분모
A8: 5 | B8: 인천(구) | C8: 2298.5726 | D8: IN-N-02 기관별 분모
A9: 6 | B9: 서울남부(구) | C9: 1881.3342 | D9: IN-N-02 기관별 분모
A10: 7 | B10: 화성직훈(교) | C10: 1749.4384 | D10: IN-N-02 기관별 분모
A11: 8 | B11: 의정부(교) | C11: 1541.9178 | D11: IN-N-02 기관별 분모
A12: 9 | B12: 여주(교) | C12: 1704.4521 | D12: IN-N-02 기관별 분모
A13: 10 | B13: 서울남부(교) | C13: 1317.0521 | D13: IN-N-02 기관별 분모
A14: 11 | B14: 춘천(교) | C14: 988.51507 | D14: IN-N-02 기관별 분모
A15: 12 | B15: 원주(교) | C15: 887.16164 | D15: IN-N-02 기관별 분모
... A57: 54 | B57: 정읍(교) | C57: 547.8274 | D57: IN-N-02 기관별 분모
B58: 합계 | C58: =SUM(C4:C57)
B59: 전국 1일 평균(서식2) | C59: ='서식2 수용인원'!D7
B60: 차이(합계−전국) | C60: =C58-C59

Sheet 서식3 마약류사범
A1: 서식 3. 마약류사범 수용현황
A2: 무엇에 쓰나요 | B2: 전체 수용자가 아니라 마약류사범을 대상으로 1인당 원가를 계산하기 위해 필요합니다.
A3: 어디서 나오나요 | B3: 교정통계연보 죄명별 수용현황, 공공데이터포털 「법무부_범죄별 경비처우급 현황」, 내부 행정통계.
A4: 꼭 봐주세요 | B4: 형기 구간은 기관에서 쓰시는 구분 그대로 적어 주셔도 됩니다. 평균 수용기간을 내는 데 씁니다.
A6: 번호 | B6: 요청 항목 | C6: 단위 | D6: 2025년 | E6: 산출 가능 여부 | F6: 비고 (모델 KEY)
A7: 1 | B7: 마약류사범 1일 평균 수용인원 | C7: 명 | E7: 미회신: 1일 평균 없음. 25.12.31 연말 현원 7,429명만 회신 | F7: IN-N-04 마약류 분모
A8: 2 | B8: 이 중 향정 사범 | C8: 명 | E8: 미회신 | F8: IN-N-04 마약류 분모
A9: 3 | B9: 마약류사범 수용 연인원 (인·일) | C9: 인·일 | E9: 미회신(회신 시트에서 이 칸에 연말 현원 7,429명이 기재됨) | F9: IN-N-05 마약류 연인원
A10: 4 | B10: 형기 6월 미만 | C10: 명 | E10: 미회신 | F10: IN-N-06 형기 분포
A11: 5 | B11: 형기 6월 ~ 1년 | C11: 명 | E11: 미회신 | F11: IN-N-06 형기 분포
A12: 6 | B12: 형기 1년 ~ 3년 | C12: 명 | E12: 미회신 | F12: IN-N-06 형기 분포
A13: 7 | B13: 형기 3년 이상 | C13: 명 | E13: 미회신 | F13: IN-N-06 형기 분포
A14: 8 | B14: 마약류사범 신입 인원 | C14: 명 | E14: 미회신 | F14: IN-N-08 회전
A15: 9 | B15: 마약류사범 출소 인원 | C15: 명 | E15: 미회신 | F15: IN-N-08 회전 / OC-01
B16: 참고) 마약류사범 수용인원은 2021년 3,314명에서 2025년 7,429명으로 늘어난 것으로 보도되었습니다.
A18: 산출이 어려운 항목의 이유 (한 줄이면 충분합니다)
B19: 사유(보안과): 해당 통계는 공식 통계로 집계 및 제공하고 있지 않음

Sheet 서식4 재활교육 실적
A1: 서식 4. 마약사범 재활교육 운영실적
A2: 무엇에 쓰나요 | B2: 재활 프로그램 1인당 비용의 아래쪽(인원)이며, 동시에 효과 분석의 대상 규모가 됩니다.
A3: 어디서 나오나요 | B3: 마약사범재활과·심리치료과의 프로그램 운영실적 보고, 교정통계연보 제Ⅲ편 제9장(심리치료).
A4: 꼭 봐주세요 | B4: 과정유형별로 나누어 주시는 것이 중요합니다. 40시간 과정과 160시간 과정은 투입 자원이 4배 차이라 합쳐 버리면 1인당 원가가 왜곡됩니다. 중도탈락 인원도 꼭 함께 적어 주십시오.
A6: 연도 | B6: 기관명 | C6: 과정유형 | D6: 과정시간 | E6: 기수(회) | F6: 개시(명) | G6: 이수(명) | H6: 중도탈락(명) | I6: 탈락 주요사유 | J6: 비고 (모델 KEY)
A7: 2026 | B7: (예시) 광주교도소 | C7: 심화 | D7: 120 | I7: 이송·출소 | J7: PG-N-01 개시 / PG-N-02 이수 / PG-N-03 탈락 / PG-D-01 인시
A8: 2024 | B8: 전국 합계 | C8: 기본 | D8: 40 | G8: 1052 | J8: PG-N-01 개시 / PG-N-02 이수 / PG-N-03 탈락 / PG-D-01 인시
A9: 2024 | B9: 전국 합계 | C9: 집중 | D9: 80 | G9: 140 | J9: PG-N-01 개시 / PG-N-02 이수 / PG-N-03 탈락 / PG-D-01 인시
A10: 2024 | B10: 전국 합계 | C10: 심화 | D10: 120 | G10: 44 | J10: PG-N-01 개시 / PG-N-02 이수 / PG-N-03 탈락 / PG-D-01 인시
A11: 2024 | B11: 전국 합계 | C11: 회복이음 | D11: 160 | G11: 91 | J11: PG-N-01 개시 / PG-N-02 이수 / PG-N-03 탈락 / PG-D-01 인시
A12: 2025 | B12: 전국 합계 | C12: 기본 | D12: 40 | G12: 1246 | J12: PG-N-01 개시 / PG-N-02 이수 / PG-N-03 탈락 / PG-D-01 인시
A13: 2025 | B13: 전국 합계 | C13: 집중 | D13: 80 | G13: 164 | J13: PG-N-01 개시 / PG-N-02 이수 / PG-N-03 탈락 / PG-D-01 인시
A14: 2025 | B14: 전국 합계 | C14: 심화 | D14: 120 | G14: 41 | J14: PG-N-01 개시 / PG-N-02 이수 / PG-N-03 탈락 / PG-D-01 인시
A15: 2025 | B15: 전국 합계 | C15: 회복이음 | D15: 160 | G15: 138 | J15: PG-N-01 개시 / PG-N-02 이수 / PG-N-03 탈락 / PG-D-01 인시
A16: 2026(7월까지) | B16: 전국 합계 | C16: 기본 | D16: 40 | G16: 753 | J16: PG-N-01 개시 / PG-N-02 이수 / PG-N-03 탈락 / PG-D-01 인시
A17: 2026(7월까지) | B17: 전국 합계 | C17: 집중 | D17: 80 | G17: 88 | J17: PG-N-01 개시 / PG-N-02 이수 / PG-N-03 탈락 / PG-D-01 인시
A18: 2026(7월까지) | B18: 전국 합계 | C18: 심화 | D18: 120 | G18: 16 | J18: PG-N-01 개시 / PG-N-02 이수 / PG-N-03 탈락 / PG-D-01 인시
A19: 2026(7월까지) | B19: 전국 합계 | C19: 회복이음 | D19: 160 | G19: 85 | J19: PG-N-01 개시 / PG-N-02 이수 / PG-N-03 탈락 / PG-D-01 인시
J20: PG-N-01 개시 / PG-N-02 이수 / PG-N-03 탈락 / PG-D-01 인시
J21: PG-N-01 개시 / PG-N-02 이수 / PG-N-03 탈락 / PG-D-01 인시
J22: PG-N-01 개시 / PG-N-02 이수 / PG-N-03 탈락 / PG-D-01 인시
J23: PG-N-01 개시 / PG-N-02 이수 / PG-N-03 탈락 / PG-D-01 인시
J24: PG-N-01 개시 / PG-N-02 이수 / PG-N-03 탈락 / PG-D-01 인시
J25: PG-N-01 개시 / PG-N-02 이수 / PG-N-03 탈락 / PG-D-01 인시
J26: PG-N-01 개시 / PG-N-02 이수 / PG-N-03 탈락 / PG-D-01 인시
J27: PG-N-01 개시 / PG-N-02 이수 / PG-N-03 탈락 / PG-D-01 인시
J28: PG-N-01 개시 / PG-N-02 이수 / PG-N-03 탈락 / PG-D-01 인시
J29: PG-N-01 개시 / PG-N-02 이수 / PG-N-03 탈락 / PG-D-01 인시
A31: 산출이 어려운 항목의 이유 (한 줄이면 충분합니다)
A32: 회신(마약사범재활팀): 이수 인원만 전국 합계로 회신. 기수·개시·중도탈락은 "별도 집계 관리하고 있지 않은 항목에는 미응답". 같은 내용 파일 3개 수령.
A35: ※ 과정유형 구분이 어려우시면 총 인원만이라도 좋습니다. 기관별 구분이 어려우시면 전국 합계도 도움이 됩니다.

Sheet 서식5 전담인력
A1: 서식 5. 재활 전담인력 현황
A2: 무엇에 쓰나요 | B2: 인건비 중 얼마를 재활 프로그램의 비용으로 볼지 정하는 데 씁니다.
A3: 어디서 나오나요 | B3: 마약사범재활과·심리치료과 정원표, 인사 자료.
A4: 꼭 봐주세요 | B4: 맨 오른쪽 '프로그램 직접투입 비율'은 정확한 값이 아니어도 됩니다. 담당자께서 보시기에 '업무시간의 70% 정도'와 같은 대략치면 충분합니다. 이 값이 없으면 인건비 전액을 프로그램 비용으로 계산하게 되어 원가가 크게 부풀려집니다.
A6: 기준연도 | B6: 기관명 | C6: 부서명 | D6: 직급·자격 | E6: 정원(명) | F6: 현원(명) | G6: 프로그램 직접투입 비율(%) | H6: 비고 (모델 KEY)
A7: 2026 | B7: (예시) 광주교도소 | C7: 마약사범재활과 | D7: 심리학 박사 | G7: 70 | H7: PG-C-04 인건비 / PG-D-02 투입비율 | I7: 직급별 구성(회신 비고)
A8: 2026 | B8: 화성직업훈련(교) | C8: 마약사범재활과 | D8: 중독심리전문가, 임상심리사 등 | E8: 11 | F8: 11 | G8: 64 | H8: PG-C-04 인건비 / PG-D-02 투입비율 | I8: 5급 1명, 6급 3명, 7급 1명, 8급 2명, 9급 4명
A9: 2026 | B9: 부산(교) | C9: 마약사범재활과 | D9: 심리학 박사, 중독심리전문가, 범죄심리전문가 등 | E9: 11 | F9: 11 | G9: 68.2 | H9: PG-C-04 인건비 / PG-D-02 투입비율 | I9: 5급 1명, 6급 2명, 7급 4명, 8급 4명
A10: 2026 | B10: 청주여자(교) | C10: 마약사범재활과 | D10: 상담학 석사, 전문상담사 1급, 청소년상담사 1급, 임상심리사 1급 등 | E10: 11 | F10: 11 | G10: 64 | H10: PG-C-04 인건비 / PG-D-02 투입비율 | I10: 5급 1명, 6급 1명, 7급 1명, 8급 3명, 9급 5명
A11: 2026 | B11: 광주(교) | C11: 마약사범재활과 | D11: 정신건강임상심리사1급, 중독심리전문가, 청소년상담사 등 | E11: 11 | F11: 11 | G11: 68.2 | H11: PG-C-04 인건비 / PG-D-02 투입비율 | I11: 5급 1명, 6급 2명, 7급 3명, 8급 2명, 9급 3명
H12: PG-C-04 인건비 / PG-D-02 투입비율
H13: PG-C-04 인건비 / PG-D-02 투입비율
H14: PG-C-04 인건비 / PG-D-02 투입비율
H15: PG-C-04 인건비 / PG-D-02 투입비율
H16: PG-C-04 인건비 / PG-D-02 투입비율
H17: PG-C-04 인건비 / PG-D-02 투입비율
H18: PG-C-04 인건비 / PG-D-02 투입비율
H19: PG-C-04 인건비 / PG-D-02 투입비율
H20: PG-C-04 인건비 / PG-D-02 투입비율
H21: PG-C-04 인건비 / PG-D-02 투입비율
A23: 산출이 어려운 항목의 이유 (한 줄이면 충분합니다)
A27: ※ 정원만 적어 주셔도 됩니다. 인건비는 직급별 공무원 보수표로 저희가 환산하겠습니다.

Sheet 서식6 재활예산
A1: 서식 6. 마약사범 재활 관련 예산 집행내역 ★ 가장 중요한 세 가지 중 하나
A2: 무엇에 쓰나요 | B2: 재활 프로그램 1인당 비용의 위쪽(총액)입니다. 서식 4의 인원으로 나누어 원단위를 만듭니다.
A3: 어디서 나오나요 | B3: 「교정·교화」 사업 내 집행내역, 마약사범재활과 운영 예산.
A4: 꼭 봐주세요 | B4: 중독재활수용동 설치비처럼 여러 해에 걸쳐 쓰이는 시설비는 설치 연도와 총액을 알려주시면 저희가 내용연수로 나누어 반영하겠습니다.
A6: 번호 | B6: 요청 항목 | C6: 단위 | D6: 2025년 | E6: 산출 가능 여부 | F6: 비고 (모델 KEY)
A7: 1 | B7: 외부 강사료·자문료 | C7: 원 | E7: 산출 불가 | F7: PG-C-05 운영비
A8: 2 | B8: 교재·검사도구 구입비 | C8: 원 | E8: 산출 불가 | F8: PG-C-05 운영비
A9: 3 | B9: 집단상담·프로그램 운영비 | C9: 원 | E9: 산출 불가 | F9: PG-C-05 운영비
A10: 4 | B10: 외부기관 위탁·민간협력비 | C10: 원 | E10: 산출 불가 | F10: PG-C-06 위탁
A11: 5 | B11: 중독재활수용동 운영비 | C11: 원 | E11: 산출 불가 | F11: PG-C-07 시설
A12: 6 | B12: 중독재활수용동 설치비 (설치연도 기재) | C12: 원 | E12: 산출 불가 | F12: PG-C-07 시설(자본)
A13: 7 | B13: 심리치료 관련 집행액 | C13: 원 | E13: 산출 불가 | F13: PG-C-02 심리치료
A14: 8 | B14: 그 밖의 마약사범 재활 집행액 | C14: 원 | E14: 산출 불가 | F14: PG-C-03 마약재활
A15: 합계 | B15: 마약사범 재활 관련 예산 총액 (비목 구분 불가) | C15: 원 | D15: 5999392000 | E15: 회신(복지과): 총액만
A17: 산출이 어려운 항목의 이유 (한 줄이면 충분합니다)
B18: 교정본부에서 관리하는 집행내역은 <교정교화> 세부사업 내에서 비목별 구분만 가능함(일반수용비, 구호 및 교정비, 공사비, 자산취득비 등)
B19: 마약사범 재활 관련 예산 총액 : 5,999,392,000원 → 예산액인지 집행액인지, 시설(설치)비 포함 여부 확인 필요
A21: ※ 항목 구분이 어려우시면 마약사범 재활 관련 총액만이라도 적어 주십시오.

Sheet 서식7 의료·검사
A1: 서식 7. 의료·약물검사 실적 및 비용
A2: 무엇에 쓰나요 | B2: 중독자에 대한 치료개입 1인당 비용을 계산합니다.
A3: 어디서 나오나요 | B3: 의료과 예산·집행내역, 교정통계연보 제Ⅲ편 제2장(위생 및 의료), 검사 계약자료.
A4: 꼭 봐주세요 | B4: 의료비를 세 갈래로 나누기 어려우시면 총액과 건강보험 예탁금 두 가지만이라도 적어 주십시오.
A6: 번호 | B6: 요청 항목 | C6: 단위 | D6: 2021년 | E6: 2022년 | F6: 2023년 | G6: 2024년 | H6: 2025년 | I6: 산출 가능 여부 | J6: 비고 (모델 KEY)
A7: 1 | B7: 수용자 의료비 집행액 (총액) | C7: 원 | D7: 3420606 | E7: 3447688 | F7: 4166977 | G7: 4495700 | H7: 5095510 | I7: 단위 확인 필요: "원"으로 표기됐으나 천원으로 추정 | J7: TX-C-01 의료 총괄
A8: 2 | B8: 건강보험 예탁금 | C8: 원 | D8: 1782500 | E8: 2000000 | F8: 2535021 | G8: 2906400 | H8: 3020629 | I8: 단위 확인 필요: "원"으로 표기됐으나 천원으로 추정 | J8: TX-C-02 건강보험
A9: 3 | B9: 자체 진료비 (의약품·재료) | C9: 원 | I9: 미생산 통계(의료과) | J9: TX-C-03 자체진료
A10: 4 | B10: 외부 의료기관 진료비 (호송 포함) | C10: 원 | I10: 미생산 통계(의료과) | J10: TX-C-04 외부진료
A11: 5 | B11: 의무직·간호직 인건비 | C11: 원 | I11: 미생산 통계(의료과) | J11: TX-C-05 의료인건비
A12: 6 | B12: 정신건강의학과 진료·향정신성 의약품비 | C12: 원 | I12: 미생산 통계(의료과) | J12: TX-C-07 정신과
A13: 7 | B13: 약물검사비 (소변) | C13: 원 | I13: 미생산 통계(의료과) | J13: TX-C-06 약물검사
A14: 8 | B14: 약물검사비 (모발) | C14: 원 | I14: 미생산 통계(의료과) | J14: TX-C-06 약물검사
A15: 9 | B15: 연간 진료 실인원 | C15: 명 | I15: 미생산 통계(의료과) | J15: TX-N-01 진료 분모
A16: 10 | B16: 연간 진료 건수(내부) | C16: 건 | D16: 7812087 | E16: 6861741 | F16: 7448490 | G16: 8299530 | H16: 8708713 | J16: TX-N-01 진료 분모
A17: 11 | B17: 외부진료 인원 | C17: 명 | D17: 39176 | E17: 41243 | F17: 48349 | G17: 49175 | H17: 46782 | J17: TX-N-02 외부진료 분모
A18: 12 | B18: 마약류사범 중 치료개입 대상 인원 | C18: 명 | I18: 미생산 통계(의료과) | J18: TX-N-03 치료개입 분모
A19: 13 | B19: 약물검사 실시 건수 | C19: 건 | I19: 미생산 통계(의료과) | J19: TX-N-04 검사 분모
A22: 산출이 어려운 항목의 이유 (한 줄이면 충분합니다)

Sheet 서식8 출소·재복역
A1: 서식 8. 출소 및 재복역 현황
A2: 무엇에 쓰나요 | B2: 재범이 원래 얼마나 일어나는지(기준선)를 확인합니다. 효과 계산의 비교 기준이 됩니다.
A3: 어디서 나오나요 | B3: 교정통계연보 제Ⅲ편 제10장(수용의 종료), 내부 재복역 추적자료.
A4: 꼭 봐주세요 | B4: 재범률은 기준에 따라 값이 크게 다릅니다. 교정본부의 '재복역률', 대검찰청 백서의 '재범률', 경찰 검거 기준이 각각 다르므로, 적어 주신 값이 어느 정의인지 한 줄만 적어 주시면 감사하겠습니다.
A6: 출소연도 | B6: 대상 | C6: 출소인원(명) | D6: 3년내 재복역(명) | E6: 재복역률(%) | F6: 6월내(명) | G6: 1년내(명) | H6: 2년내(명) | I6: 정의·산출기준 | J6: 비고 (모델 KEY)
A7: 2019 | B7: (예시) 마약류사범 | I7: 3년 이내 재복역 기준 | J7: OC-01 코호트 / OC-02 기저재범률(r0) / OC-05 경과기간
A8: 2024 | B8: 마약류사범 | J8: OC-01 코호트 / OC-02 기저재범률(r0) / OC-05 경과기간
A9: 2025 | B9: 마약류사범 | J9: OC-01 코호트 / OC-02 기저재범률(r0) / OC-05 경과기간
J10: OC-01 코호트 / OC-02 기저재범률(r0) / OC-05 경과기간
J11: OC-01 코호트 / OC-02 기저재범률(r0) / OC-05 경과기간
J12: OC-01 코호트 / OC-02 기저재범률(r0) / OC-05 경과기간
J13: OC-01 코호트 / OC-02 기저재범률(r0) / OC-05 경과기간
A15: 산출이 어려운 항목의 이유 (한 줄이면 충분합니다)

Sheet 서식9 이수별 재복역
A1: 서식 9. 재활교육 이수 여부별 재복역 교차표 ★ 13건 중 가장 중요합니다
A2: 무엇에 쓰나요 | B2: 재활교육이 재범을 얼마나 줄이는지 계산합니다. 이 표 하나만 있으면 효과 추정이 가능합니다.
A3: 어디서 나오나요 | B3: 출소자 명부와 재활교육 이수 기록을 연결한 집계. 개인 자료는 필요하지 않습니다.
A4: 꼭 봐주세요 | B4: 특정 칸의 인원이 5명 미만이면 인접 구간과 합쳐 주십시오. 또한 '미이수'에 중도탈락자를 포함하셨는지 비고란 옆에 표시해 주시면 감사하겠습니다. 두 집단은 성격이 달라 구분이 필요합니다.
A6: 출소연도 | B6: 과정유형 | C6: 구분 | D6: 출소인원(명) | E6: 3년내 재복역(명) | F6: 재복역률(%) | G6: 중도탈락 포함 여부 | H6: 비고 (모델 KEY)
A7: 2019 | B7: (예시) 전체 | C7: 이수 | D7: 439 | E7: 178 | F7: 40.6 | H7: OC-03 → Δr(재범감소폭) 및 r0(기저재범률) 산출
A8: 2019 | B8: (예시) 전체 | C8: 미이수 | D8: 492 | E8: 247 | F8: 50.2 | G8: 포함 | H8: OC-03 → Δr(재범감소폭) 및 r0(기저재범률) 산출
A9: 2025 | B9: 전체 | C9: 이수 | H9: OC-03 → Δr(재범감소폭) 및 r0(기저재범률) 산출
A10: 2025 | B10: 전체 | C10: 미이수 | H10: OC-03 → Δr(재범감소폭) 및 r0(기저재범률) 산출
A11: 2025 | B11: 전체 | C11: 중도탈락 | H11: OC-03 → Δr(재범감소폭) 및 r0(기저재범률) 산출
H12: OC-03 → Δr(재범감소폭) 및 r0(기저재범률) 산출
H13: OC-03 → Δr(재범감소폭) 및 r0(기저재범률) 산출
H14: OC-03 → Δr(재범감소폭) 및 r0(기저재범률) 산출
H15: OC-03 → Δr(재범감소폭) 및 r0(기저재범률) 산출
H16: OC-03 → Δr(재범감소폭) 및 r0(기저재범률) 산출
H17: OC-03 → Δr(재범감소폭) 및 r0(기저재범률) 산출
A19: 산출이 어려운 항목의 이유 (한 줄이면 충분합니다)
A23: ※ 출소연도별 구분이 어려우시면 여러 해를 합산한 값도 좋습니다(예: 2018~2021년 합계). 이 항목만 시간이 걸리신다면 다른 항목보다 늦게 별도로 회신해 주셔도 됩니다.

Sheet 서식10 인적특성
A1: 서식 10. 이수·미이수 집단의 인적 특성
A2: 무엇에 쓰나요 | B2: 두 집단이 원래 비슷한 사람들이었는지 확인합니다. 이수자가 처음부터 재범 위험이 낮은 사람들이었다면 교육의 효과가 실제보다 커 보이게 됩니다.
A3: 어디서 나오나요 | B3: 서식 9와 같은 대상 집단의 인적사항 집계.
A4: 꼭 봐주세요 | B4: 구성비(%)나 평균값만으로 충분합니다. 개인별 자료는 필요하지 않습니다.
A6: 출소연도 | B6: 구분 | C6: 인원(명) | D6: 평균 연령 | E6: 평균 형기(월) | F6: 평균 전과 범수 | G6: 징벌 1회 이상 비율(%) | H6: 30세 미만 비율(%) | I6: 비고 (모델 KEY)
A7: 2019 | B7: (예시) 이수 | C7: 439 | I7: OC-04 → Δr 신뢰성 진단(표준화 평균차)
A8: 2025 | B8: 이수 | I8: OC-04 → Δr 신뢰성 진단(표준화 평균차)
A9: 2025 | B9: 미이수 | I9: OC-04 → Δr 신뢰성 진단(표준화 평균차)
A10: 2025 | B10: 중도탈락 | I10: OC-04 → Δr 신뢰성 진단(표준화 평균차)
I11: OC-04 → Δr 신뢰성 진단(표준화 평균차)
I12: OC-04 → Δr 신뢰성 진단(표준화 평균차)
I13: OC-04 → Δr 신뢰성 진단(표준화 평균차)
I14: OC-04 → Δr 신뢰성 진단(표준화 평균차)
I15: OC-04 → Δr 신뢰성 진단(표준화 평균차)
A17: 산출이 어려운 항목의 사유 (한 줄이면 충분합니다)
A21: ※ 연령과 형기 두 가지만이라도 적어 주시면 기초적인 비교가 가능합니다.

Sheet 서식11 산출기준
A1: 서식 11. 통계 산출기준 정의서
A2: 무엇에 쓰나요 | B2: 같은 '인원'이라도 정의가 다르면 1인당 금액이 달라집니다. 짧은 설명이면 충분합니다.
A3: 어디서 나오나요 | B3: 내부 통계 작성 지침, 담당자 설명.
A4: 꼭 봐주세요 | B4: 별도 서식 없이 자유롭게 적어 주시거나, 전화·전자우편으로 설명해 주셔도 됩니다.
A6: 번호 | B6: 대상 통계 | C6: 인원 정의 (1일평균/연인원/실인원/재적 등) | D6: 기준일 | E6: 산출식 | F6: 연도별 변경 이력 | G6: 비고 (모델 KEY)
A7: 예시 | B7: 1일 평균 수용인원 | C7: 일별 재적인원의 연간 평균 | D7: 매일 24시 | E7: Σ(일별 재적) ÷ 365 | G7: MT-04 통계 산출기준
A8: 1 | B8: 1일 평균 수용인원 | G8: MT-04 통계 산출기준
A9: 2 | B9: 수용 연인원 | G9: MT-04 통계 산출기준
A10: 3 | B10: 마약류사범 수용인원 | G10: MT-04 통계 산출기준
A11: 4 | B11: 재활교육 이수 인원 | G11: MT-04 통계 산출기준
A12: 5 | B12: 진료 실인원 | G12: MT-04 통계 산출기준
A13: 6 | B13: 출소자 재복역률 | G13: MT-04 통계 산출기준
G14: MT-04 통계 산출기준
G15: MT-04 통계 산출기준
G16: MT-04 통계 산출기준
G17: MT-04 통계 산출기준
G18: MT-04 통계 산출기준
A20: 산출이 어려운 항목의 이유 (한 줄이면 충분합니다)

Sheet 별도요청 타기관
A1: 별도 요청. 치료보호·보호관찰 예산 및 인원 ※ 교정본부 소관이 아닙니다
A2: 무엇에 쓰나요 | B2: 출소 후 사후관리 비용입니다. 해외 문헌은 사후관리 없는 교도소 내 치료의 효과가 지속되지 않는다는 데 일치하므로, 이 항목이 비면 비용은 과소·편익은 과대로 계산됩니다.
A3: 어디서 나오나요 | B3: 보건복지부(마약류 중독자 치료보호), 법무부 범죄예방정책국(보호관찰·치료명령), 법무부 치료처우과(국립법무병원).
A4: 꼭 봐주세요 | B4: 이 시트는 교정본부에 요청드리는 것이 아닙니다. 해당 기관에 별도 공문으로 요청할 항목을 정리해 둔 것입니다.
A6: 번호 | B6: 요청 항목 | C6: 단위 | D6: 2021년 | E6: 2022년 | F6: 2023년 | G6: 2024년 | H6: 2025년 | I6: 산출 가능 여부 | J6: 비고 (모델 KEY)
A7: 1 | B7: 마약류 중독자 치료보호 예산액 (복지부) | C7: 원 | I7: 미회신(복지부) | J7: CU-C-03 사후관리 비용풀
A8: 2 | B8: 마약류 중독자 치료보호 집행액 (복지부) | C8: 원 | I8: 미회신(복지부) | J8: CU-C-03 사후관리 비용풀
A9: 3 | B9: 치료보호 지원 인원 (복지부) | C9: 명 | I9: 미회신(복지부) | J9: CU-C-03 사후관리 분모
A10: 4 | B10: 치료보호 지정기관 수 / 병상 수 (복지부) | C10: 개소/병상 | I10: 미회신(복지부) | J10: CU-C-03 참고
A11: 5 | B11: 보호관찰 대상 마약류사범 인원 (범죄예방정책국) | C11: 명 | D11: 3675 | E11: 3762 | F11: 4178 | G11: 5078 | H11: 5391 | I11: 회신(범죄예방정책국) | J11: CU-N-02 사회내처우 분모
A12: 6 | B12: 치료명령·치료조건부 가석방 인원 (범죄예방정책국) | C12: 명 | D12: 234 | E12: 194 | F12: 219 | G12: 247 | H12: 332 | I12: 회신(범죄예방정책국) | J12: CU-N-02 사회내처우 분모
A13: 7 | B13: 보호관찰 약물사범 관련 예산 (범죄예방정책국) | C13: 원 | I13: 산출 불가(범죄예방정책국) | J13: CU-C-02 사회내처우 비용풀
A14: 8 | B14: 국립법무병원 운영 결산액 (치료처우과) | C14: 원 | D14: 8508000000 | E14: 9770000000 | F14: 11521000000 | G14: 12146000000 | H14: 12357000000 | I14: 회신(치료처우과): 병원 전체 결산 | J14: CU-C-01 치료감호 비용풀
A15: 9 | B15: 국립법무병원 약물중독(2호) 연평균 수용인원 | C15: 명 | D15: 31 | E15: 31 | F15: 30 | G15: 31 | H15: 24 | I15: 회신(치료처우과) | J15: CU-N-01 치료감호 분모
A17: ※ 이 표의 1~3행이 채워져야 사후관리 1인당 원가(UC-12)를 산출할 수 있고, 그래야 증분비용 ΔC 의 세 번째 항이 완성됩니다.
A20: 산출이 어려운 항목의 이유 (한 줄이면 충분합니다)
B21: 범죄예방정책국: 마약 키트 구입 구입 등 특정 사업비 예산이 편성되어 있으나, 그 외 에 보호관찰 분야 인건비 및 사업비 등 대부분의 예산이 별도 편성되어 있지 않아 산출에 어려움이 있습니다.
B22: 복지부 미회신. 치료보호 인원은 2025 마약류 범죄백서 표 3-82로 대체 가능(2021~2025: 280, 421, 641, 875, 1,649명). 예산은 대체 자료 없음.

Sheet KEY 설명
A1: 비고란 KEY 값 설명 (연구진용)
A2: 각 서식 맨 오른쪽 비고란의 값이 무엇을 뜻하는지 정리한 것입니다. 담당자께서 작성하실 내용은 없습니다.
A4: KEY 앞자리 | B4: 뜻 | C4: 설명 | D4: 예 | E4: 쓰이는 곳 | F4: 관련 서식
A5: IN-C | B5: 투옥 비용풀 | C5: 수용 그 자체에 드는 비용의 총액(분자) | D5: IN-C-02 급식비 | E5: UC-01 총원가 / UC-02 변동원가 | F5: 서식 1
A6: IN-N | B6: 투옥 분모 | C6: 위 비용을 나눌 인원·기간 | D6: IN-N-01 1일 평균 수용인원 | E6: UC-01·02·03 의 분모 | F6: 서식 2·3
A7: PG-C | B7: 투입 비용풀 | C7: 재활 프로그램에 드는 비용의 총액 | D7: PG-C-04 전담인력 인건비 | E7: UC-06·07 의 분자 | F7: 서식 1·5·6
A8: PG-N | B8: 투입 분모 | C8: 프로그램 참여 인원 | D8: PG-N-02 과정유형별 이수 인원 | E8: UC-06 의 분모 | F8: 서식 4
A9: PG-D | B9: 투입 배부기준 | C9: 인건비를 과정별로 나눌 기준(인시·투입비율) | D9: PG-D-01 총 인시 | E9: UC-07 의 분모 | F9: 서식 4·5
A10: TX-C | B10: 치료 비용풀 | C10: 의료·약물치료 개입 비용의 총액 | D10: TX-C-03 자체 진료비 | E10: UC-09·10 의 분자 | F10: 서식 7
A11: TX-N | B11: 치료 분모 | C11: 치료개입 대상 인원·건수 | D11: TX-N-03 치료개입 대상 인원 | E11: UC-10 의 분모 | F11: 서식 7
A12: CU-C | B12: 감호·사후관리 비용풀 | C12: 치료감호와 출소 후 사후관리 비용 | D12: CU-C-03 치료보호 예산 | E12: UC-12 의 분자 | F12: 별도요청
A13: CU-N | B13: 감호·사후관리 분모 | C13: 치료감호·보호관찰 대상 인원 | D13: CU-N-01 국립법무병원 인원 | E13: UC-11·12 의 분모 | F13: 별도요청
A14: OC | B14: 성과 | C14: 재범·출소 관련 성과 지표 | D14: OC-03 이수별 재복역 교차표 | E14: Δr(재범감소폭) · r0(기저재범률) | F14: 서식 8·9·10
A15: MT | B15: 정합성 | C15: 원단위를 검증하기 위한 기준 자료 | D15: MT-04 통계 산출기준 | E15: 전 원단위의 분모 정합성 검증 | F15: 서식 11·12
A18: 최종 산식
A19: 1인당 증분비용 ΔC = UC-06(프로그램) + UC-10(치료개입) + UC-12(사후관리) + ΔM × UC-02(수용기간 차이)
A20: 1인당 편익 B = r0(기저재범률) × Δr(재범감소폭) × SC(재범 1건당 사회적 비용)
A21: 판정지표 B/C = B ÷ ΔC (사회적 할인율 4.5%, 분석기간 5년)
A23: ※ UC-01(수용 총원가)은 재활교육을 받은 사람과 받지 않은 사람 모두에게 똑같이 발생하므로 증분비용 ΔC 에는 넣지 않습니다. 수용기간에 차이가 있을 때만 한계원가 UC-02 로 환산해 반영합니다.

Sheet 구조_안내
A1: 구조-v1 · 마약류 사회적 비용 모델의 칸·변수 구조
A2: 작성 2026-10-21. 산식은 넣지 않고, 칸과 입력 변수의 자리만 고정한 판이다. 산식은 팀 결정과 공개통계 수집 뒤에 「원단위계산」처럼 별도 시트로 붙인다.
A4: 시트 | B4: 하는 일
A5: 구조_칸 | B5: 구현 모델 39칸. 칸마다 비용 종류, 계산 단위, 적용 인원, λ 적용 여부, 연간 총액·생애 누적·SCᵣ 포함 여부, 합산되는 곳을 고정한다. 변수 수와 미입력 수는 「구조_변수」에서 자동으로 센다.
A6: 구조_변수 | B6: 칸마다 필요한 입력 변수의 자리. 값 칸(노란색)에 숫자를 넣으면 상태가 자동으로 바뀐다.
A7: 구조_스위치 | B7: 구조에 걸린 미결정 사항 6가지. 칸은 만들어 두고 선택값만 바꾼다. 「구조_칸」의 일부 열이 이 값을 따라간다.
A8: 구조_중복규칙 | B8: 한쪽에만 넣어야 하는 6쌍(작성표준 명세 공통 원칙 5).
A9: 구조_집계 | B9: 절별·상태별 변수 개수. 지금 무엇이 입력되었고 무엇이 남았는지 한눈에 본다.
A11: 칸 색 | B11: 뜻
A12: 노란 칸 | B12: 입력하는 칸: 「구조_변수」의 출처 종류·기준연도·값·메모, 「구조_스위치」의 현재 선택
A13: 회색 칸 | B13: 잠긴 구조: 칸 ID, 이름, 성격, 변수 ID, 변수 이름, 단위, 출처 상세. 바꾸려면 판을 올린다(아래)
A14: 파란 글씨 | B14: 입력 칸의 글자(저장소 잠금 점검이 파란 글씨 칸을 입력 칸으로 인식한다)
A15: 초록 글씨 | B15: 다른 시트에서 가져온 값(스위치 반영 등)
A16: 검정 글씨 | B16: 계산식(상태, 개수)
... A27: 예시 행 | B27: 구조_변수 3-3a-2: 교도소 일반회계 세출 결산 · 원 · 직접 · 서식 회신 · 「자료요청 2차」 hwpx(복지과) · 2025 · 1,699,217,000,000 → 상태 "입력됨"

Sheet 구조_칸
A1: 칸 ID | B1: 절·묶음 | C1: 칸 이름 | D1: 1단계 출처 | E1: 비용 종류 | F1: 계산 단위 | G1: 적용 인원 | H1: λ 적용 | I1: 연간 총액에 포함 | J1: 생애 누적 | K1: SCᵣ에 포함 | L1: 합산되는 곳 | M1: 관련 스위치 | N1: 현재 분류(10.21) | O1: 변수 수 | P1: 미입력 변수 | Q1: 입력 진척(연결 제외) | R1: 비고
A2: 제1절 의료·복지
A3: 1-1a | B3: 제1절 의료·복지 | C3: 건강보험·의료급여 진료비 | D3: 직접의료비 | E3: DC | F3: 연간 총액 | G3: 진료 실인원 | H3: =IF(구조_스위치!$D$7="보정 없음","아니오",IF(구조_스위치!$D$7="잠재 치료비 별도","별도 표기","결정 대기")) | I3: 예 | J3: 아니오 | K3: 예(1인당) | L3: 제1절 소계 | M3: S6 | N3: B | O3: =COUNTIF(구조_변수!$B:$B,$A3) | P3: =COUNTIFS(구조_변수!$B:$B,$A3,구조_변수!$J:$J,"미입력") | Q3: =IF(O3=0,"-",IF(O3-COUNTIFS(구조_변수!$B:$B,$A3,구조_변수!$J:$J,"연결")=0,"연결만",(O3-P3-COUNTIFS(구조_변수!$B:$B,$A3,구조_변수!$J:$J,"연결"))/(O3-COUNTIFS(구조_변수!$B:$B,$A3,구조_변수!$J:$J,"연결")))) | R3: 물질 관련 장애 상병. 치료보호와 중복 제거
A4: 1-1b | B4: 제1절 의료·복지 | C4: 치료보호 국고지원 | D4: 직접의료비(국고지원) | E4: DC | F4: 연간 총액 | G4: 치료보호 인원 | H4: 아니오 | I4: 예 | J4: 아니오 | K4: 예(1인당) | L4: 제1절 소계 | N4: B | O4: =COUNTIF(구조_변수!$B:$B,$A4) | P4: =COUNTIFS(구조_변수!$B:$B,$A4,구조_변수!$J:$J,"미입력") | Q4: =IF(O4=0,"-",IF(O4-COUNTIFS(구조_변수!$B:$B,$A4,구조_변수!$J:$J,"연결")=0,"연결만",(O4-P4-COUNTIFS(구조_변수!$B:$B,$A4,구조_변수!$J:$J,"연결"))/(O4-COUNTIFS(구조_변수!$B:$B,$A4,구조_변수!$J:$J,"연결")))) | R4: 2024. 7. 건강보험 적용 이후 1-1a와 겹침
A5: 1-1c | B5: 제1절 의료·복지 | C5: 교정시설 수용자 의료비 | D5: 없음 | E5: DC | F5: 연간 총액 | G5: 마약류 수용인원 | H5: 아니오 | I5: 예 | J5: 아니오 | K5: 예(1인당) | L5: =IF(구조_스위치!$D$2="제1절 1","제1절 소계","제3절 소계") | M5: S1 | N5: C | O5: =COUNTIF(구조_변수!$B:$B,$A5) | P5: =COUNTIFS(구조_변수!$B:$B,$A5,구조_변수!$J:$J,"미입력") | Q5: =IF(O5=0,"-",IF(O5-COUNTIFS(구조_변수!$B:$B,$A5,구조_변수!$J:$J,"연결")=0,"연결만",(O5-P5-COUNTIFS(구조_변수!$B:$B,$A5,구조_변수!$J:$J,"연결"))/(O5-COUNTIFS(구조_변수!$B:$B,$A5,구조_변수!$J:$J,"연결")))) | R5: 서식7 단위(천원) 확인 필요
A6: 1-2 | B6: 제1절 의료·복지 | C6: 직접 비의료비(간접의료비) | D6: 간접의료비 × 38.1% | E6: DC | F6: 연간 총액 | G6: 1-1과 같음 | H6: 1-1 따름 | I6: 예 | J6: 아니오 | K6: 예(1인당) | L6: 제1절 소계 | M6: S6 | N6: C | O6: =COUNTIF(구조_변수!$B:$B,$A6) | P6: =COUNTIFS(구조_변수!$B:$B,$A6,구조_변수!$J:$J,"미입력") | Q6: =IF(O6=0,"-",IF(O6-COUNTIFS(구조_변수!$B:$B,$A6,구조_변수!$J:$J,"연결")=0,"연결만",(O6-P6-COUNTIFS(구조_변수!$B:$B,$A6,구조_변수!$J:$J,"연결"))/(O6-COUNTIFS(구조_변수!$B:$B,$A6,구조_변수!$J:$J,"연결")))) | R6: 비율 출처 보고서 미확인
A7: 1-3 | B7: 제1절 의료·복지 | C7: 정신건강·복지 지원 | D7: 의료보조비(재정의) | E7: DC | F7: 연간 총액 | G7: 사업 대상자 | H7: 아니오 | I7: 예 | J7: 아니오 | K7: 아니오 | L7: 제1절 소계 | N7: N | O7: =COUNTIF(구조_변수!$B:$B,$A7) | P7: =COUNTIFS(구조_변수!$B:$B,$A7,구조_변수!$J:$J,"미입력") | Q7: =IF(O7=0,"-",IF(O7-COUNTIFS(구조_변수!$B:$B,$A7,구조_변수!$J:$J,"연결")=0,"연결만",(O7-P7-COUNTIFS(구조_변수!$B:$B,$A7,구조_변수!$J:$J,"연결"))/(O7-COUNTIFS(구조_변수!$B:$B,$A7,구조_변수!$J:$J,"연결")))) | R7: 이전지출 제외, 센터 운영비로 재정의
A8: 제2절 생산성
A9: 2-1 | B9: 제2절 생산성 | C9: 조기 사망 생산성 손실 | D9: 조기사망비용(PV) | E9: IC | F9: 연간 총액 | G9: 실제 사망자 | H9: 아니오 | I9: 예 | J9: 아니오 | K9: 아니오 | L9: 제2절 소계 | N9: B | O9: =COUNTIF(구조_변수!$B:$B,$A9) | P9: =COUNTIFS(구조_변수!$B:$B,$A9,구조_변수!$J:$J,"미입력") | Q9: =IF(O9=0,"-",IF(O9-COUNTIFS(구조_변수!$B:$B,$A9,구조_변수!$J:$J,"연결")=0,"연결만",(O9-P9-COUNTIFS(구조_변수!$B:$B,$A9,구조_변수!$J:$J,"연결"))/(O9-COUNTIFS(구조_변수!$B:$B,$A9,구조_변수!$J:$J,"연결")))) | R9: 사망자 3개년 평균 검토
A10: 2-2 | B10: 제2절 생산성 | C10: 이환·입원 생산성 손실 | D10: 의료이용 생산손실 | E10: IC | F10: 연간 총액 | G10: 진료 실인원 | H10: =IF(구조_스위치!$D$7="결정 대기","결정 대기","1-1a 따름") | I10: 예 | J10: 아니오 | K10: 예(1인당) | L10: 제2절 소계 | M10: S6 | N10: B | O10: =COUNTIF(구조_변수!$B:$B,$A10) | P10: =COUNTIFS(구조_변수!$B:$B,$A10,구조_변수!$J:$J,"미입력") | Q10: =IF(O10=0,"-",IF(O10-COUNTIFS(구조_변수!$B:$B,$A10,구조_변수!$J:$J,"연결")=0,"연결만",(O10-P10-COUNTIFS(구조_변수!$B:$B,$A10,구조_변수!$J:$J,"연결"))/(O10-COUNTIFS(구조_변수!$B:$B,$A10,구조_변수!$J:$J,"연결")))) | R10: 외래 1회 = 1/3일 가정
A11: 2-3a | B11: 제2절 생산성 | C11: 구금 기간 생산성 손실 | D11: 없음(신설) | E11: IC | F11: 연간 총액 | G11: 마약류 1일 평균 수용인원 | H11: 아니오 | I11: 예 | J11: 아니오 | K11: 예(1인당) | L11: 제2절 소계 | M11: S4 | N11: N | O11: =COUNTIF(구조_변수!$B:$B,$A11) | P11: =COUNTIFS(구조_변수!$B:$B,$A11,구조_변수!$J:$J,"미입력") | Q11: =IF(O11=0,"-",IF(O11-COUNTIFS(구조_변수!$B:$B,$A11,구조_변수!$J:$J,"연결")=0,"연결만",(O11-P11-COUNTIFS(구조_변수!$B:$B,$A11,구조_변수!$J:$J,"연결"))/(O11-COUNTIFS(구조_변수!$B:$B,$A11,구조_변수!$J:$J,"연결")))) | R11: 2-3b와 같은 기간 중복 금지
A12: 2-3b | B12: 제2절 생산성 | C12: 의존 상태 미취업 손실 | D12: 없음(신설) | E12: IC | F12: 연간 총액 | G12: N* 중 의존 상태 인원 | H12: 예 | I12: 예 | J12: 아니오 | K12: 예(1인당) | L12: 제2절 소계 | M12: S4 | N12: R1 | O12: =COUNTIF(구조_변수!$B:$B,$A12) | P12: =COUNTIFS(구조_변수!$B:$B,$A12,구조_변수!$J:$J,"미입력") | Q12: =IF(O12=0,"-",IF(O12-COUNTIFS(구조_변수!$B:$B,$A12,구조_변수!$J:$J,"연결")=0,"연결만",(O12-P12-COUNTIFS(구조_변수!$B:$B,$A12,구조_변수!$J:$J,"연결"))/(O12-COUNTIFS(구조_변수!$B:$B,$A12,구조_변수!$J:$J,"연결")))) | R12: 의존 비율 자료 없음
A13: 2-3c | B13: 제2절 생산성 | C13: 연령대별 생애 손실 PV_a | D13: 별도 축 세대별 손실 | E13: IC | F13: 1인당 생애 현재가치 | G13: 연령 5구간 신규 진입자 | H13: 아니오 | I13: 아니오 | J13: 예 | K13: 아니오 | L13: 생애 누적표(제6절) | M13: S4 | N13: C | O13: =COUNTIF(구조_변수!$B:$B,$A13) | P13: =COUNTIFS(구조_변수!$B:$B,$A13,구조_변수!$J:$J,"미입력") | Q13: =IF(O13=0,"-",IF(O13-COUNTIFS(구조_변수!$B:$B,$A13,구조_변수!$J:$J,"연결")=0,"연결만",(O13-P13-COUNTIFS(구조_변수!$B:$B,$A13,구조_변수!$J:$J,"연결"))/(O13-COUNTIFS(구조_변수!$B:$B,$A13,구조_변수!$J:$J,"연결")))) | R13: 연간 총액에 더하지 않음
A14: 2-3d | B14: 제2절 생산성 | C14: 재범 누적 TC_코호트 | D14: 별도 축 재범 누적 | E14: IC | F14: 코호트 누적 현재가치 | G14: 재범자 코호트 | H14: 아니오 | I14: 아니오 | J14: 예 | K14: 아니오 | L14: 생애 누적표(제6절) | M14: S4 | N14: C | O14: =COUNTIF(구조_변수!$B:$B,$A14) | P14: =COUNTIFS(구조_변수!$B:$B,$A14,구조_변수!$J:$J,"미입력") | Q14: =IF(O14=0,"-",IF(O14-COUNTIFS(구조_변수!$B:$B,$A14,구조_변수!$J:$J,"연결")=0,"연결만",(O14-P14-COUNTIFS(구조_변수!$B:$B,$A14,구조_변수!$J:$J,"연결"))/(O14-COUNTIFS(구조_변수!$B:$B,$A14,구조_변수!$J:$J,"연결")))) | R14: C_1회 = SCᵣ
A15: 제3절 형사사법
A16: 3-1a | B16: 제3절 형사사법 | C16: 검찰 단계 비용 | D16: 수사·기소 | E16: =구조_스위치!$D$8 | F16: 연간 총액 · 1인당 | G16: 실제 검거·처리 인원 | H16: 아니오 | I16: 예 | J16: 아니오 | K16: 예(1건당) | L16: 제3절 소계 | M16: S7 | N16: A | O16: =COUNTIF(구조_변수!$B:$B,$A16) | P16: =COUNTIFS(구조_변수!$B:$B,$A16,구조_변수!$J:$J,"미입력") | Q16: =IF(O16=0,"-",IF(O16-COUNTIFS(구조_변수!$B:$B,$A16,구조_변수!$J:$J,"연결")=0,"연결만",(O16-P16-COUNTIFS(구조_변수!$B:$B,$A16,구조_변수!$J:$J,"연결"))/(O16-COUNTIFS(구조_변수!$B:$B,$A16,구조_변수!$J:$J,"연결"))))
A17: 3-1b | B17: 제3절 형사사법 | C17: 경찰·관세청·해경 수사 비용 | D17: 수사 | E17: =구조_스위치!$D$8 | F17: 연간 총액 | G17: 실제 검거 인원 | H17: 아니오 | I17: 예 | J17: 아니오 | K17: 예(1건당) | L17: 제3절 소계 | M17: S7 | N17: B | O17: =COUNTIF(구조_변수!$B:$B,$A17) | P17: =COUNTIFS(구조_변수!$B:$B,$A17,구조_변수!$J:$J,"미입력") | Q17: =IF(O17=0,"-",IF(O17-COUNTIFS(구조_변수!$B:$B,$A17,구조_변수!$J:$J,"연결")=0,"연결만",(O17-P17-COUNTIFS(구조_변수!$B:$B,$A17,구조_변수!$J:$J,"연결"))/(O17-COUNTIFS(구조_변수!$B:$B,$A17,구조_변수!$J:$J,"연결")))) | R17: 전담 예산과 배분 추정분 구분
A18: 3-2 | B18: 제3절 형사사법 | C18: 재판·국선변호 비용 | D18: 재판 | E18: =구조_스위치!$D$8 | F18: 연간 총액 | G18: 1심 처리 인원 | H18: 아니오 | I18: 예 | J18: 아니오 | K18: 예(1건당) | L18: 제3절 소계 | M18: S7 | N18: B | O18: =COUNTIF(구조_변수!$B:$B,$A18) | P18: =COUNTIFS(구조_변수!$B:$B,$A18,구조_변수!$J:$J,"미입력") | Q18: =IF(O18=0,"-",IF(O18-COUNTIFS(구조_변수!$B:$B,$A18,구조_변수!$J:$J,"연결")=0,"연결만",(O18-P18-COUNTIFS(구조_변수!$B:$B,$A18,구조_변수!$J:$J,"연결"))/(O18-COUNTIFS(구조_변수!$B:$B,$A18,구조_변수!$J:$J,"연결")))) | R18: 검찰 기소 단계와 경계 설정
A19: 3-3a | B19: 제3절 형사사법 | C19: 교정 수용 관리비(UC-01) | D19: 수용 | E19: =구조_스위치!$D$8 | F19: 연간 총액 · 1인당 | G19: 마약류 1일 평균 수용인원 | H19: 아니오 | I19: 예 | J19: 아니오 | K19: 예(1건당) | L19: 제3절 소계 | M19: S7 | N19: A | O19: =COUNTIF(구조_변수!$B:$B,$A19) | P19: =COUNTIFS(구조_변수!$B:$B,$A19,구조_변수!$J:$J,"미입력") | Q19: =IF(O19=0,"-",IF(O19-COUNTIFS(구조_변수!$B:$B,$A19,구조_변수!$J:$J,"연결")=0,"연결만",(O19-P19-COUNTIFS(구조_변수!$B:$B,$A19,구조_변수!$J:$J,"연결"))/(O19-COUNTIFS(구조_변수!$B:$B,$A19,구조_변수!$J:$J,"연결")))) | R19: 기본 2,378만 원 / 상한 2,651만 원 / 원고 2,396만 원 중 확정
A20: 3-3b | B20: 제3절 형사사법 | C20: 보호관찰·이수명령 비용 | D20: 보호관찰 | E20: =구조_스위치!$D$8 | F20: 연간 총액 | G20: 보호관찰 대상 마약류사범 | H20: 아니오 | I20: 예 | J20: 아니오 | K20: 예(1건당) | L20: 제3절 소계 | M20: S7 | N20: B | O20: =COUNTIF(구조_변수!$B:$B,$A20) | P20: =COUNTIFS(구조_변수!$B:$B,$A20,구조_변수!$J:$J,"미입력") | Q20: =IF(O20=0,"-",IF(O20-COUNTIFS(구조_변수!$B:$B,$A20,구조_변수!$J:$J,"연결")=0,"연결만",(O20-P20-COUNTIFS(구조_변수!$B:$B,$A20,구조_변수!$J:$J,"연결"))/(O20-COUNTIFS(구조_변수!$B:$B,$A20,구조_변수!$J:$J,"연결")))) | R20: 예산 배분 가정
A21: 3-3c | B21: 제3절 형사사법 | C21: 치료감호(국립법무병원 2호) | D21: 치료감호 | E21: =구조_스위치!$D$8 | F21: 연간 총액 | G21: 2호 연평균 수용인원 | H21: 아니오 | I21: 예 | J21: 아니오 | K21: 아니오 | L21: =IF(구조_스위치!$D$3="제3절 3","제3절 소계","제1절 소계") | M21: S2 | N21: B | O21: =COUNTIF(구조_변수!$B:$B,$A21) | P21: =COUNTIFS(구조_변수!$B:$B,$A21,구조_변수!$J:$J,"미입력") | Q21: =IF(O21=0,"-",IF(O21-COUNTIFS(구조_변수!$B:$B,$A21,구조_변수!$J:$J,"연결")=0,"연결만",(O21-P21-COUNTIFS(구조_변수!$B:$B,$A21,구조_변수!$J:$J,"연결"))/(O21-COUNTIFS(구조_변수!$B:$B,$A21,구조_변수!$J:$J,"연결")))) | R21: 병원 전체 결산을 2호 비율로 배분
A22: 제4절 피해자·주위
A23: 4-1 | B23: 제4절 피해자·주위 | C23: 2차 범죄 직접 피해(불특정 다수) | D23: 사회혼란 · 불특정 다수 피해 | E23: IC | F23: 연간 총액 | G23: 범죄·사고 건수 | H23: 아니오 | I23: 예 | J23: 아니오 | K23: 예(귀속분) | L23: 제4절 소계 | N23: B | O23: =COUNTIF(구조_변수!$B:$B,$A23) | P23: =COUNTIFS(구조_변수!$B:$B,$A23,구조_변수!$J:$J,"미입력") | Q23: =IF(O23=0,"-",IF(O23-COUNTIFS(구조_변수!$B:$B,$A23,구조_변수!$J:$J,"연결")=0,"연결만",(O23-P23-COUNTIFS(구조_변수!$B:$B,$A23,구조_변수!$J:$J,"연결"))/(O23-COUNTIFS(구조_변수!$B:$B,$A23,구조_변수!$J:$J,"연결")))) | R23: 제5절 2와 중복 금지
A24: 4-2a | B24: 제4절 피해자·주위 | C24: 피해자 사망·중상 PGS | D24: 사망 PGS | E24: PGS | F24: 연간 총액 | G24: 2차 범죄·사고 사망자·부상자 | H24: 아니오 | I24: 예 | J24: 아니오 | K24: 예(귀속분) | L24: 제4절 소계 | N24: B | O24: =COUNTIF(구조_변수!$B:$B,$A24) | P24: =COUNTIFS(구조_변수!$B:$B,$A24,구조_변수!$J:$J,"미입력") | Q24: =IF(O24=0,"-",IF(O24-COUNTIFS(구조_변수!$B:$B,$A24,구조_변수!$J:$J,"연결")=0,"연결만",(O24-P24-COUNTIFS(구조_변수!$B:$B,$A24,구조_변수!$J:$J,"연결"))/(O24-COUNTIFS(구조_변수!$B:$B,$A24,구조_변수!$J:$J,"연결")))) | R24: KOTI 원단위
A25: 4-2b | B25: 제4절 피해자·주위 | C25: 중독자 본인 고통 PGS | D25: 중독 PGS | E25: PGS | F25: 연간 총액 | G25: N* 중 의존 상태 인원 | H25: 예 | I25: =IF(구조_스위치!$D$4="포함","예",IF(구조_스위치!$D$4="제외","아니오","결정 대기")) | J25: 아니오 | K25: 아니오 | L25: 제4절 소계 | M25: S3 | N25: N | O25: =COUNTIF(구조_변수!$B:$B,$A25) | P25: =COUNTIFS(구조_변수!$B:$B,$A25,구조_변수!$J:$J,"미입력") | Q25: =IF(O25=0,"-",IF(O25-COUNTIFS(구조_변수!$B:$B,$A25,구조_변수!$J:$J,"연결")=0,"연결만",(O25-P25-COUNTIFS(구조_변수!$B:$B,$A25,구조_변수!$J:$J,"연결"))/(O25-COUNTIFS(구조_변수!$B:$B,$A25,구조_변수!$J:$J,"연결"))))
A26: 4-3 | B26: 제4절 피해자·주위 | C26: 가족·주변인 케어 | D26: 가족·지역사회 파급 | E26: IC | F26: 연간 총액 | G26: 가족 수 | H26: 결정 필요 | I26: 예(산출 시) | J26: 아니오 | K26: 아니오 | L26: 제4절 소계 | N26: R1 | O26: =COUNTIF(구조_변수!$B:$B,$A26) | P26: =COUNTIFS(구조_변수!$B:$B,$A26,구조_변수!$J:$J,"미입력") | Q26: =IF(O26=0,"-",IF(O26-COUNTIFS(구조_변수!$B:$B,$A26,구조_변수!$J:$J,"연결")=0,"연결만",(O26-P26-COUNTIFS(구조_변수!$B:$B,$A26,구조_변수!$J:$J,"연결"))/(O26-COUNTIFS(구조_변수!$B:$B,$A26,구조_변수!$J:$J,"연결")))) | R26: 자료 없으면 정성 기술
A27: 제5절 기타
A28: 5-1 | B28: 제5절 기타 | C28: 예방·홍보·R&D 예산 | D28: 없음(신설) | E28: DC | F28: 연간 총액 | G28: 해당 없음 | H28: 해당 없음 | I28: 예 | J28: 아니오 | K28: 아니오 | L28: 제5절 소계 | N28: N | O28: =COUNTIF(구조_변수!$B:$B,$A28) | P28: =COUNTIFS(구조_변수!$B:$B,$A28,구조_변수!$J:$J,"미입력") | Q28: =IF(O28=0,"-",IF(O28-COUNTIFS(구조_변수!$B:$B,$A28,구조_변수!$J:$J,"연결")=0,"연결만",(O28-P28-COUNTIFS(구조_변수!$B:$B,$A28,구조_변수!$J:$J,"연결"))/(O28-COUNTIFS(구조_변수!$B:$B,$A28,구조_변수!$J:$J,"연결")))) | R28: 제1절 3·제3절과 겹치는 사업 제외
A29: 5-2a | B29: 제5절 기타 | C29: 범죄 공포(WTP) | D29: 사회혼란 · 범죄 공포 | E29: IC | F29: 연간 총액 | G29: 전국 성인 인구 | H29: 해당 없음 | I29: =IF(구조_스위치!$D$6="산출","예",IF(구조_스위치!$D$6="정성 기술","아니오","결정 대기")) | J29: 아니오 | K29: 아니오 | L29: 제5절 소계 | M29: S5 | N29: R1 | O29: =COUNTIF(구조_변수!$B:$B,$A29) | P29: =COUNTIFS(구조_변수!$B:$B,$A29,구조_변수!$J:$J,"미입력") | Q29: =IF(O29=0,"-",IF(O29-COUNTIFS(구조_변수!$B:$B,$A29,구조_변수!$J:$J,"연결")=0,"연결만",(O29-P29-COUNTIFS(구조_변수!$B:$B,$A29,구조_변수!$J:$J,"연결"))/(O29-COUNTIFS(구조_변수!$B:$B,$A29,구조_변수!$J:$J,"연결"))))
A30: 5-2b | B30: 제5절 기타 | C30: 방어적 행동 | D30: 사회혼란 · 방어행동 | E30: IC | F30: 연간 총액 | G30: 전국 성인 인구 | H30: 해당 없음 | I30: =IF(구조_스위치!$D$6="산출","예",IF(구조_스위치!$D$6="정성 기술","아니오","결정 대기")) | J30: 아니오 | K30: 아니오 | L30: 제5절 소계 | M30: S5 | N30: R1 | O30: =COUNTIF(구조_변수!$B:$B,$A30) | P30: =COUNTIFS(구조_변수!$B:$B,$A30,구조_변수!$J:$J,"미입력") | Q30: =IF(O30=0,"-",IF(O30-COUNTIFS(구조_변수!$B:$B,$A30,구조_변수!$J:$J,"연결")=0,"연결만",(O30-P30-COUNTIFS(구조_변수!$B:$B,$A30,구조_변수!$J:$J,"연결"))/(O30-COUNTIFS(구조_변수!$B:$B,$A30,구조_변수!$J:$J,"연결"))))
A31: 제6절 종합
A32: 6-1 | B32: 제6절 종합 | C32: N* 실질 사용자 수 | D32: 총괄식 | E32: 지표 | F32: 명 | G32: 검거 인원 | H32: 예 | I32: 해당 없음 | J32: 해당 없음 | K32: 해당 없음 | L32: 1인당 비용 분모 | N32: A | O32: =COUNTIF(구조_변수!$B:$B,$A32) | P32: =COUNTIFS(구조_변수!$B:$B,$A32,구조_변수!$J:$J,"미입력") | Q32: =IF(O32=0,"-",IF(O32-COUNTIFS(구조_변수!$B:$B,$A32,구조_변수!$J:$J,"연결")=0,"연결만",(O32-P32-COUNTIFS(구조_변수!$B:$B,$A32,구조_변수!$J:$J,"연결"))/(O32-COUNTIFS(구조_변수!$B:$B,$A32,구조_변수!$J:$J,"연결")))) | R32: λ 1·10·28.57 민감도
A33: 6-2 | B33: 제6절 종합 | C33: λ 10 비교·GDP 대비 비율 | D33: 기대효과 | E33: 지표 | F33: 비율 · 원 | G33: 해당 없음 | H33: λ 10 기준 | I33: 해당 없음 | J33: 해당 없음 | K33: 해당 없음 | L33: 제6절 표 | N33: N | O33: =COUNTIF(구조_변수!$B:$B,$A33) | P33: =COUNTIFS(구조_변수!$B:$B,$A33,구조_변수!$J:$J,"미입력") | Q33: =IF(O33=0,"-",IF(O33-COUNTIFS(구조_변수!$B:$B,$A33,구조_변수!$J:$J,"연결")=0,"연결만",(O33-P33-COUNTIFS(구조_변수!$B:$B,$A33,구조_변수!$J:$J,"연결"))/(O33-COUNTIFS(구조_변수!$B:$B,$A33,구조_변수!$J:$J,"연결")))) | R33: 박성수(2018) 2016년 2조 2,389억 원과 비교
A34: 6-3 | B34: 제6절 종합 | C34: 연간 총액 ↔ 생애 누적 분리표 | D34: 없음 | E34: 표 | F34: 해당 없음 | G34: 해당 없음 | H34: 해당 없음 | I34: 해당 없음 | J34: 해당 없음 | K34: 해당 없음 | L34: 제6절 표 | N34: N | O34: =COUNTIF(구조_변수!$B:$B,$A34) | P34: =COUNTIFS(구조_변수!$B:$B,$A34,구조_변수!$J:$J,"미입력") | Q34: =IF(O34=0,"-",IF(O34-COUNTIFS(구조_변수!$B:$B,$A34,구조_변수!$J:$J,"연결")=0,"연결만",(O34-P34-COUNTIFS(구조_변수!$B:$B,$A34,구조_변수!$J:$J,"연결"))/(O34-COUNTIFS(구조_변수!$B:$B,$A34,구조_변수!$J:$J,"연결")))) | R34: 값 없음(표 틀)
A35: 비용편익 ΔC
A36: CB-1 | B36: 비용편익 ΔC | C36: UC-07 재활교육 1인시당 원가 | D36: C2 프로그램 | E36: ΔC | F36: 원/인시 | G36: 이수 인시 | H36: 해당 없음 | I36: 해당 없음 | J36: 해당 없음 | K36: 해당 없음 | L36: UC-06 | N36: A | O36: =COUNTIF(구조_변수!$B:$B,$A36) | P36: =COUNTIFS(구조_변수!$B:$B,$A36,구조_변수!$J:$J,"미입력") | Q36: =IF(O36=0,"-",IF(O36-COUNTIFS(구조_변수!$B:$B,$A36,구조_변수!$J:$J,"연결")=0,"연결만",(O36-P36-COUNTIFS(구조_변수!$B:$B,$A36,구조_변수!$J:$J,"연결"))/(O36-COUNTIFS(구조_변수!$B:$B,$A36,구조_변수!$J:$J,"연결"))))
A37: CB-2 | B37: 비용편익 ΔC | C37: UC-06 과정유형별 1인당 원가 | D37: C2 프로그램 | E37: ΔC | F37: 원/인 | G37: 과정별 이수 인원 | H37: 해당 없음 | I37: 해당 없음 | J37: 해당 없음 | K37: 해당 없음 | L37: ΔC | N37: C | O37: =COUNTIF(구조_변수!$B:$B,$A37) | P37: =COUNTIFS(구조_변수!$B:$B,$A37,구조_변수!$J:$J,"미입력") | Q37: =IF(O37=0,"-",IF(O37-COUNTIFS(구조_변수!$B:$B,$A37,구조_변수!$J:$J,"연결")=0,"연결만",(O37-P37-COUNTIFS(구조_변수!$B:$B,$A37,구조_변수!$J:$J,"연결"))/(O37-COUNTIFS(구조_변수!$B:$B,$A37,구조_변수!$J:$J,"연결")))) | R37: 분모를 개시 인원으로 바꿀지 검토
A38: CB-3 | B38: 비용편익 ΔC | C38: UC-10 치료개입 원가 | D38: C3 치료 | E38: ΔC | F38: 원/인·년 | G38: 치료개입 대상 인원 | H38: 해당 없음 | I38: 해당 없음 | J38: 해당 없음 | K38: 해당 없음 | L38: ΔC | N38: R1 | O38: =COUNTIF(구조_변수!$B:$B,$A38) | P38: =COUNTIFS(구조_변수!$B:$B,$A38,구조_변수!$J:$J,"미입력") | Q38: =IF(O38=0,"-",IF(O38-COUNTIFS(구조_변수!$B:$B,$A38,구조_변수!$J:$J,"연결")=0,"연결만",(O38-P38-COUNTIFS(구조_변수!$B:$B,$A38,구조_변수!$J:$J,"연결"))/(O38-COUNTIFS(구조_변수!$B:$B,$A38,구조_변수!$J:$J,"연결"))))
A39: CB-4 | B39: 비용편익 ΔC | C39: UC-12 사후관리 원가 | D39: 없음(신설) | E39: ΔC | F39: 원/인·년 | G39: 치료보호 지원 인원 | H39: 해당 없음 | I39: 해당 없음 | J39: 해당 없음 | K39: 해당 없음 | L39: ΔC (÷(1+r)^t) | N39: B | O39: =COUNTIF(구조_변수!$B:$B,$A39) | P39: =COUNTIFS(구조_변수!$B:$B,$A39,구조_변수!$J:$J,"미입력") | Q39: =IF(O39=0,"-",IF(O39-COUNTIFS(구조_변수!$B:$B,$A39,구조_변수!$J:$J,"연결")=0,"연결만",(O39-P39-COUNTIFS(구조_변수!$B:$B,$A39,구조_변수!$J:$J,"연결"))/(O39-COUNTIFS(구조_변수!$B:$B,$A39,구조_변수!$J:$J,"연결")))) | R39: 1-1b와 같은 자료
A40: CB-5 | B40: 비용편익 ΔC | C40: ΔM × UC-02 수용기간 차이 | D40: C1 수용(제외) | E40: ΔC | F40: 원/인 | G40: 이수·미이수 수용기간 차이 | H40: 해당 없음 | I40: 해당 없음 | J40: 해당 없음 | K40: 해당 없음 | L40: ΔC | N40: C | O40: =COUNTIF(구조_변수!$B:$B,$A40) | P40: =COUNTIFS(구조_변수!$B:$B,$A40,구조_변수!$J:$J,"미입력") | Q40: =IF(O40=0,"-",IF(O40-COUNTIFS(구조_변수!$B:$B,$A40,구조_변수!$J:$J,"연결")=0,"연결만",(O40-P40-COUNTIFS(구조_변수!$B:$B,$A40,구조_변수!$J:$J,"연결"))/(O40-COUNTIFS(구조_변수!$B:$B,$A40,구조_변수!$J:$J,"연결"))))
...

Sheet 구조_변수
A1: 변수 ID | B1: 칸 ID | C1: 변수 이름 | D1: 단위 | E1: 역할 | F1: 출처 종류 | G1: 출처 상세 | H1: 기준연도 | I1: 값 | J1: 상태 | K1: 메모
A2: G-01 | B2: 공통 | C2: 기준 연도 | D2: 연 | E2: 직접 | F2: 가정 | G2: 명세 공통 원칙 1 | H2: 2025 | I2: 2025 | J2: =IF(F2="연결","연결",IF(I2="","미입력",IF(F2="가정","가정",IF(OR(F2="문헌",F2="공개통계·예산서"),"대체 입력","입력됨"))))
A3: G-02 | B3: 공통 | C3: 할인율 r | D3: 비율 | E3: 직접 | F3: 가정 | G3: 명세·인계메모 기본값(민감도 3~5%) | H3: 2025 | I3: 0.045 | J3: =IF(F3="연결","연결",IF(I3="","미입력",IF(F3="가정","가정",IF(OR(F3="문헌",F3="공개통계·예산서"),"대체 입력","입력됨"))))
A4: G-03 | B4: 공통 | C4: 암수율 λ | D4: 배 | E4: 직접 | F4: 문헌 | G4: 박성수·백민석(2019) | I4: 28.57 | J4: =IF(F4="연결","연결",IF(I4="","미입력",IF(F4="가정","가정",IF(OR(F4="문헌",F4="공개통계·예산서"),"대체 입력","입력됨")))) | K4: λ 10 비교 병행
A5: G-04 | B5: 공통 | C5: 마약류 단속 인원 N검거 | D5: 명 | E5: 직접 | F5: 백서 | G5: 2025 마약류 범죄백서 표 3-1 | H5: 2025 | I5: 23403 | J5: =IF(F5="연결","연결",IF(I5="","미입력",IF(F5="가정","가정",IF(OR(F5="문헌",F5="공개통계·예산서"),"대체 입력","입력됨"))))
A6: G-05 | B6: 공통 | C6: 교정시설 1일 평균 수용인원 | D6: 명 | E6: 직접 | F6: 서식 회신 | G6: 서식2 1번(보안과, 26.9.7) | H6: 2025 | I6: 63680 | J6: =IF(F6="연결","연결",IF(I6="","미입력",IF(F6="가정","가정",IF(OR(F6="문헌",F6="공개통계·예산서"),"대체 입력","입력됨"))))
A7: G-06 | B7: 공통 | C7: 마약류 수용인원 | D7: 명 | E7: 직접 | F7: 서식 회신 | G7: 서식3 1번 요청. 회신은 연말 현원 | H7: 2025 | I7: 7429 | J7: =IF(F7="연결","연결",IF(I7="","미입력",IF(F7="가정","가정",IF(OR(F7="문헌",F7="공개통계·예산서"),"대체 입력","입력됨")))) | K7: 1일 평균 미회신 → 연말 현원 대체
A8: G-07 | B8: 공통 | C8: 연령별 연평균 임금 | D8: 원 | E8: 직접 | F8: 공개통계·예산서 | G8: 고용노동부 고용형태별 근로실태조사 | J8: =IF(F8="연결","연결",IF(I8="","미입력",IF(F8="가정","가정",IF(OR(F8="문헌",F8="공개통계·예산서"),"대체 입력","입력됨"))))
A9: G-08 | B9: 공통 | C9: 연령별 경제활동참가율 | D9: 비율 | E9: 직접 | F9: 공개통계·예산서 | G9: 통계청 경제활동인구조사 | J9: =IF(F9="연결","연결",IF(I9="","미입력",IF(F9="가정","가정",IF(OR(F9="문헌",F9="공개통계·예산서"),"대체 입력","입력됨"))))
A10: G-09 | B10: 공통 | C10: 연령별 취업률 | D10: 비율 | E10: 직접 | F10: 공개통계·예산서 | G10: 통계청 경제활동인구조사 | J10: =IF(F10="연결","연결",IF(I10="","미입력",IF(F10="가정","가정",IF(OR(F10="문헌",F10="공개통계·예산서"),"대체 입력","입력됨"))))
A11: G-10 | B11: 공통 | C11: 소비자물가지수 환산계수 | D11: 배 | E11: 직접 | F11: 공개통계·예산서 | G11: 통계청 CPI | J11: =IF(F11="연결","연결",IF(I11="","미입력",IF(F11="가정","가정",IF(OR(F11="문헌",F11="공개통계·예산서"),"대체 입력","입력됨")))) | K11: 과거 원단위 2025년 가격 환산
A12: G-11 | B12: 공통 | C12: N* 중 의존(장애) 상태 비율 | D12: 비율 | E12: 직접 | F12: 문헌 | G12: 대응 자료 없음 | J12: =IF(F12="연결","연결",IF(I12="","미입력",IF(F12="가정","가정",IF(OR(F12="문헌",F12="공개통계·예산서"),"대체 입력","입력됨")))) | K12: R1 원인. 문헌 비율 도입 시 가정
A13: G-12 | B13: 공통 | C13: 전국 성인 인구 | D13: 명 | E13: 직접 | F13: 공개통계·예산서 | G13: 통계청 주민등록인구 | J13: =IF(F13="연결","연결",IF(I13="","미입력",IF(F13="가정","가정",IF(OR(F13="문헌",F13="공개통계·예산서"),"대체 입력","입력됨"))))
A14: G-13 | B14: 공통 | C14: 명목 GDP | D14: 원 | E14: 직접 | F14: 공개통계·예산서 | G14: 한국은행 국민계정 | J14: =IF(F14="연결","연결",IF(I14="","미입력",IF(F14="가정","가정",IF(OR(F14="문헌",F14="공개통계·예산서"),"대체 입력","입력됨"))))
A15: 1-1a-1 | B15: 1-1a | C15: 물질 관련 장애 상병 건강보험 진료비 | D15: 원 | E15: 직접 | F15: 공개통계·예산서 | G15: 심평원 질병세분류 통계 | J15: =IF(F15="연결","연결",IF(I15="","미입력",IF(F15="가정","가정",IF(OR(F15="문헌",F15="공개통계·예산서"),"대체 입력","입력됨")))) | K15: 알코올·담배 상병 제외
A16: 1-1a-2 | B16: 1-1a | C16: 같은 상병 의료급여 진료비 | D16: 원 | E16: 직접 | F16: 공개통계·예산서 | G16: 심평원 의료급여 통계 | J16: =IF(F16="연결","연결",IF(I16="","미입력",IF(F16="가정","가정",IF(OR(F16="문헌",F16="공개통계·예산서"),"대체 입력","입력됨"))))
A17: 1-1a-3 | B17: 1-1a | C17: 상병별 원인기여율 | D17: 비율 | E17: 직접 | F17: 문헌 | G17: 물질 관련 장애 1.0, 동반질환 문헌값 | J17: =IF(F17="연결","연결",IF(I17="","미입력",IF(F17="가정","가정",IF(OR(F17="문헌",F17="공개통계·예산서"),"대체 입력","입력됨"))))
A18: 1-1a-4 | B18: 1-1a | C18: 진료 실인원 | D18: 명 | E18: 보조 | F18: 공개통계·예산서 | G18: 심평원 | J18: =IF(F18="연결","연결",IF(I18="","미입력",IF(F18="가정","가정",IF(OR(F18="문헌",F18="공개통계·예산서"),"대체 입력","입력됨")))) | K18: S6 보정에 사용
A19: 1-1b-1 | B19: 1-1b | C19: 치료보호 집행액 | D19: 원 | E19: 직접 | F19: 별도요청 | G19: 별도요청 2번(복지부) | H19: 2025 | J19: =IF(F19="연결","연결",IF(I19="","미입력",IF(F19="가정","가정",IF(OR(F19="문헌",F19="공개통계·예산서"),"대체 입력","입력됨")))) | K19: 미회신 → 복지부 예산서로 대체 가능
A20: 1-1b-2 | B20: 1-1b | C20: 치료보호 인원 | D20: 명 | E20: 직접 | F20: 백서 | G20: 백서 표 3-82(복지부 정신건강관리과) | H20: 2025 | I20: 1649 | J20: =IF(F20="연결","연결",IF(I20="","미입력",IF(F20="가정","가정",IF(OR(F20="문헌",F20="공개통계·예산서"),"대체 입력","입력됨")))) | K20: 외래 1,422 · 입원 227
A21: 1-1c-1 | B21: 1-1c | C21: 수용자 의료비 집행액 | D21: 원 | E21: 직접 | F21: 서식 회신 | G21: 서식7 1번(의료과, 26.9.7) | H21: 2025 | I21: 5095510000 | J21: =IF(F21="연결","연결",IF(I21="","미입력",IF(F21="가정","가정",IF(OR(F21="문헌",F21="공개통계·예산서"),"대체 입력","입력됨")))) | K21: "원" 칸에 5,095,510 기재 → 천원 가정해 원으로 환산
A22: 1-1c-2 | B22: 1-1c | C22: 1일 평균 수용인원 | D22: 명 | E22: 보조 | F22: 연결 | G22: → G-05 | J22: =IF(F22="연결","연결",IF(I22="","미입력",IF(F22="가정","가정",IF(OR(F22="문헌",F22="공개통계·예산서"),"대체 입력","입력됨"))))
A23: 1-1c-3 | B23: 1-1c | C23: 마약류 수용인원 | D23: 명 | E23: 보조 | F23: 연결 | G23: → G-06 | J23: =IF(F23="연결","연결",IF(I23="","미입력",IF(F23="가정","가정",IF(OR(F23="문헌",F23="공개통계·예산서"),"대체 입력","입력됨"))))
A24: 1-2-1 | B24: 1-2 | C24: 직접 비의료비 비율 | D24: 비율 | E24: 직접 | F24: 가정 | G24: 한국보건사회연구원(보고서명·연도 미확인) | I24: 0.381 | J24: =IF(F24="연결","연결",IF(I24="","미입력",IF(F24="가정","가정",IF(OR(F24="문헌",F24="공개통계·예산서"),"대체 입력","입력됨"))))
A25: 1-3-1 | B25: 1-3 | C25: 함께한걸음센터 운영비 중 재활분 | D25: 원 | E25: 직접 | F25: 공개통계·예산서 | G25: 식약처·복지부 예산서 | J25: =IF(F25="연결","연결",IF(I25="","미입력",IF(F25="가정","가정",IF(OR(F25="문헌",F25="공개통계·예산서"),"대체 입력","입력됨"))))
A26: 1-3-2 | B26: 1-3 | C26: 중독관리통합지원센터 운영비 중 마약류 귀속분 | D26: 원 | E26: 직접 | F26: 공개통계·예산서 | G26: 복지부 예산서 | J26: =IF(F26="연결","연결",IF(I26="","미입력",IF(F26="가정","가정",IF(OR(F26="문헌",F26="공개통계·예산서"),"대체 입력","입력됨")))) | K26: 귀속 비율 필요
A27: 1-3-3 | B27: 1-3 | C27: 한국마약퇴치운동본부 재활사업비 | D27: 원 | E27: 직접 | F27: 공개통계·예산서 | G27: 마퇴본부 결산 | J27: =IF(F27="연결","연결",IF(I27="","미입력",IF(F27="가정","가정",IF(OR(F27="문헌",F27="공개통계·예산서"),"대체 입력","입력됨")))) | K27: 예방·홍보비는 5-1로
A28: 2-1-1 | B28: 2-1 | C28: 성·연령별 약물 중독 사망자 수 | D28: 명 | E28: 직접 | F28: 공개통계·예산서 | G28: 통계청 사망원인통계 | J28: =IF(F28="연결","연결",IF(I28="","미입력",IF(F28="가정","가정",IF(OR(F28="문헌",F28="공개통계·예산서"),"대체 입력","입력됨")))) | K28: 3개년 평균
A29: 2-1-2 | B29: 2-1 | C29: 근로 종료 연령 | D29: 세 | E29: 직접 | F29: 가정 | G29: 팀 결정 | J29: =IF(F29="연결","연결",IF(I29="","미입력",IF(F29="가정","가정",IF(OR(F29="문헌",F29="공개통계·예산서"),"대체 입력","입력됨"))))
A30: 2-2-1 | B30: 2-2 | C30: 물질 관련 장애 입원일수 | D30: 일 | E30: 직접 | F30: 공개통계·예산서 | G30: 심평원 | J30: =IF(F30="연결","연결",IF(I30="","미입력",IF(F30="가정","가정",IF(OR(F30="문헌",F30="공개통계·예산서"),"대체 입력","입력됨"))))
A31: 2-2-2 | B31: 2-2 | C31: 물질 관련 장애 외래일수 | D31: 일 | E31: 직접 | F31: 공개통계·예산서 | G31: 심평원 | J31: =IF(F31="연결","연결",IF(I31="","미입력",IF(F31="가정","가정",IF(OR(F31="문헌",F31="공개통계·예산서"),"대체 입력","입력됨"))))
A32: 2-2-3 | B32: 2-2 | C32: 외래 1회 환산 일수 | D32: 일 | E32: 직접 | F32: 가정 | G32: 제안서 4장(1/3일) | I32: 0.33333333 | J32: =IF(F32="연결","연결",IF(I32="","미입력",IF(F32="가정","가정",IF(OR(F32="문헌",F32="공개통계·예산서"),"대체 입력","입력됨"))))
A33: 2-3a-1 | B33: 2-3a | C33: 마약류 1일 평균 수용인원 | D33: 명 | E33: 직접 | F33: 서식 회신 | G33: 서식3 1번(미회신) | H33: 2025 | J33: =IF(F33="연결","연결",IF(I33="","미입력",IF(F33="가정","가정",IF(OR(F33="문헌",F33="공개통계·예산서"),"대체 입력","입력됨")))) | K33: 교정통계연보로 추정 가능
A34: 2-3b-1 | B34: 2-3b | C34: 의존 상태 인원 | D34: 명 | E34: 직접 | F34: 연결 | G34: → G-04 × G-03 × G-11 | J34: =IF(F34="연결","연결",IF(I34="","미입력",IF(F34="가정","가정",IF(OR(F34="문헌",F34="공개통계·예산서"),"대체 입력","입력됨"))))
A35: 2-3c-1 | B35: 2-3c | C35: 연령 구간별 사범 수 | D35: 명 | E35: 직접 | F35: 백서 | G35: 백서 표 3-6(19세 이하 674 · 20대 6,913 · 30대 6,986 · 40대 3,925 · 50대 2,428 · 60세 이상 1,990) | H35: 2025 | J35: =IF(F35="연결","연결",IF(I35="","미입력",IF(F35="가정","가정",IF(OR(F35="문헌",F35="공개통계·예산서"),"대체 입력","입력됨")))) | K35: 구간 재구성 필요(15~19/20~24/…)
A36: 2-3c-2 | B36: 2-3c | C36: 생산성 손실률 δ | D36: 비율 | E36: 직접 | F36: 가정 | G36: 팀 결정 | J36: =IF(F36="연결","연결",IF(I36="","미입력",IF(F36="가정","가정",IF(OR(F36="문헌",F36="공개통계·예산서"),"대체 입력","입력됨"))))
A37: 2-3c-3 | B37: 2-3c | C37: 실질임금상승률 g | D37: 비율 | E37: 직접 | F37: 가정 | G37: 팀 결정 | J37: =IF(F37="연결","연결",IF(I37="","미입력",IF(F37="가정","가정",IF(OR(F37="문헌",F37="공개통계·예산서"),"대체 입력","입력됨"))))
A38: 2-3c-4 | B38: 2-3c | C38: 구간별 잔여 기대근로연수 T_a | D38: 년 | E38: 직접 | F38: 가정 | G38: 근로 종료 연령에서 산출 | J38: =IF(F38="연결","연결",IF(I38="","미입력",IF(F38="가정","가정",IF(OR(F38="문헌",F38="공개통계·예산서"),"대체 입력","입력됨"))))
A39: 2-3d-1 | B39: 2-3d | C39: 재범 확률 p | D39: 비율 | E39: 직접 | F39: 문헌 | G39: 김도균·나종민(2025) 미이수 집단 | I39: 0.502 | J39: =IF(F39="연결","연결",IF(I39="","미입력",IF(F39="가정","가정",IF(OR(F39="문헌",F39="공개통계·예산서"),"대체 입력","입력됨")))) | K39: 서식8·9 오면 교체
A40: 2-3d-2 | B40: 2-3d | C40: 재범 시점 t_k | D40: 년 | E40: 직접 | F40: 서식 회신 | G40: 서식8(미회신) | J40: =IF(F40="연결","연결",IF(I40="","미입력",IF(F40="가정","가정",IF(OR(F40="문헌",F40="공개통계·예산서"),"대체 입력","입력됨"))))
...

Sheet 구조_집계
A1: 변수 입력 현황 (구조_변수 J열 기준, 자동 집계)
A3: 묶음 | B3: 칸 ID 앞자리 규칙 | C3: 입력됨 | D3: 대체 입력 | E3: 가정 | F3: 연결 | G3: 미입력 | H3: 합계 | I3: 입력 비율
A4: 공통 | B4: 공통 | C4: =COUNTIFS(구조_변수!$B$2:$B$111,$B4,구조_변수!$J$2:$J$111,"입력됨") | D4: =COUNTIFS(구조_변수!$B$2:$B$111,$B4,구조_변수!$J$2:$J$111,"대체 입력") | E4: =COUNTIFS(구조_변수!$B$2:$B$111,$B4,구조_변수!$J$2:$J$111,"가정") | F4: =COUNTIFS(구조_변수!$B$2:$B$111,$B4,구조_변수!$J$2:$J$111,"연결") | G4: =COUNTIFS(구조_변수!$B$2:$B$111,$B4,구조_변수!$J$2:$J$111,"미입력") | H4: =SUM(C4:G4) | I4: =IF(H4=0,"-",(C4+D4+E4)/(H4-F4))
A5: 제1절 의료·복지 | B5: 1-* | C5: =COUNTIFS(구조_변수!$B$2:$B$111,$B5,구조_변수!$J$2:$J$111,"입력됨") | D5: =COUNTIFS(구조_변수!$B$2:$B$111,$B5,구조_변수!$J$2:$J$111,"대체 입력") | E5: =COUNTIFS(구조_변수!$B$2:$B$111,$B5,구조_변수!$J$2:$J$111,"가정") | F5: =COUNTIFS(구조_변수!$B$2:$B$111,$B5,구조_변수!$J$2:$J$111,"연결") | G5: =COUNTIFS(구조_변수!$B$2:$B$111,$B5,구조_변수!$J$2:$J$111,"미입력") | H5: =SUM(C5:G5) | I5: =IF(H5=0,"-",(C5+D5+E5)/(H5-F5))
A6: 제2절 생산성 | B6: 2-* | C6: =COUNTIFS(구조_변수!$B$2:$B$111,$B6,구조_변수!$J$2:$J$111,"입력됨") | D6: =COUNTIFS(구조_변수!$B$2:$B$111,$B6,구조_변수!$J$2:$J$111,"대체 입력") | E6: =COUNTIFS(구조_변수!$B$2:$B$111,$B6,구조_변수!$J$2:$J$111,"가정") | F6: =COUNTIFS(구조_변수!$B$2:$B$111,$B6,구조_변수!$J$2:$J$111,"연결") | G6: =COUNTIFS(구조_변수!$B$2:$B$111,$B6,구조_변수!$J$2:$J$111,"미입력") | H6: =SUM(C6:G6) | I6: =IF(H6=0,"-",(C6+D6+E6)/(H6-F6))
A7: 제3절 형사사법 | B7: 3-* | C7: =COUNTIFS(구조_변수!$B$2:$B$111,$B7,구조_변수!$J$2:$J$111,"입력됨") | D7: =COUNTIFS(구조_변수!$B$2:$B$111,$B7,구조_변수!$J$2:$J$111,"대체 입력") | E7: =COUNTIFS(구조_변수!$B$2:$B$111,$B7,구조_변수!$J$2:$J$111,"가정") | F7: =COUNTIFS(구조_변수!$B$2:$B$111,$B7,구조_변수!$J$2:$J$111,"연결") | G7: =COUNTIFS(구조_변수!$B$2:$B$111,$B7,구조_변수!$J$2:$J$111,"미입력") | H7: =SUM(C7:G7) | I7: =IF(H7=0,"-",(C7+D7+E7)/(H7-F7))
A8: 제4절 피해자·주위 | B8: 4-* | C8: =COUNTIFS(구조_변수!$B$2:$B$111,$B8,구조_변수!$J$2:$J$111,"입력됨") | D8: =COUNTIFS(구조_변수!$B$2:$B$111,$B8,구조_변수!$J$2:$J$111,"대체 입력") | E8: =COUNTIFS(구조_변수!$B$2:$B$111,$B8,구조_변수!$J$2:$J$111,"가정") | F8: =COUNTIFS(구조_변수!$B$2:$B$111,$B8,구조_변수!$J$2:$J$111,"연결") | G8: =COUNTIFS(구조_변수!$B$2:$B$111,$B8,구조_변수!$J$2:$J$111,"미입력") | H8: =SUM(C8:G8) | I8: =IF(H8=0,"-",(C8+D8+E8)/(H8-F8))
A9: 제5절 기타 | B9: 5-* | C9: =COUNTIFS(구조_변수!$B$2:$B$111,$B9,구조_변수!$J$2:$J$111,"입력됨") | D9: =COUNTIFS(구조_변수!$B$2:$B$111,$B9,구조_변수!$J$2:$J$111,"대체 입력") | E9: =COUNTIFS(구조_변수!$B$2:$B$111,$B9,구조_변수!$J$2:$J$111,"가정") | F9: =COUNTIFS(구조_변수!$B$2:$B$111,$B9,구조_변수!$J$2:$J$111,"연결") | G9: =COUNTIFS(구조_변수!$B$2:$B$111,$B9,구조_변수!$J$2:$J$111,"미입력") | H9: =SUM(C9:G9) | I9: =IF(H9=0,"-",(C9+D9+E9)/(H9-F9))
A10: 제6절 종합 | B10: 6-* | C10: =COUNTIFS(구조_변수!$B$2:$B$111,$B10,구조_변수!$J$2:$J$111,"입력됨") | D10: =COUNTIFS(구조_변수!$B$2:$B$111,$B10,구조_변수!$J$2:$J$111,"대체 입력") | E10: =COUNTIFS(구조_변수!$B$2:$B$111,$B10,구조_변수!$J$2:$J$111,"가정") | F10: =COUNTIFS(구조_변수!$B$2:$B$111,$B10,구조_변수!$J$2:$J$111,"연결") | G10: =COUNTIFS(구조_변수!$B$2:$B$111,$B10,구조_변수!$J$2:$J$111,"미입력") | H10: =SUM(C10:G10) | I10: =IF(H10=0,"-",(C10+D10+E10)/(H10-F10))
